Internal Server Error: /create/
Traceback (most recent call last):
  File "/usr/local/lib/python3.11/site-packages/django/core/handlers/exception.py", line 55, in inner
    response = get_response(request)
               ^^^^^^^^^^^^^^^^^^^^^
  File "/usr/local/lib/python3.11/site-packages/django/core/handlers/base.py", line 197, in _get_response
    response = wrapped_callback(request, *callback_args, **callback_kwargs)
               ^^^^^^^^^^^^^^^^^^^^^^^^^^^^^^^^^^^^^^^^^^^^^^^^^^^^^^^^^^^^
  File "/usr/local/lib/python3.11/site-packages/django/contrib/auth/decorators.py", line 23, in _wrapper_view
    return view_func(request, *args, **kwargs)
           ^^^^^^^^^^^^^^^^^^^^^^^^^^^^^^^^^^^
  File "/Users/taramanjimacbookpro/Documents/GitHub/OpenHackU2023_Ritskomachi/todo/views.py", line 149, in create_todo
    return render(request, 'todo/todo_form.html', {'form': form})
           ^^^^^^^^^^^^^^^^^^^^^^^^^^^^^^^^^^^^^^^^^^^^^^^^^^^^^^
  File "/usr/local/lib/python3.11/site-packages/django/shortcuts.py", line 24, in render
    content = loader.render_to_string(template_name, context, request, using=using)
              ^^^^^^^^^^^^^^^^^^^^^^^^^^^^^^^^^^^^^^^^^^^^^^^^^^^^^^^^^^^^^^^^^^^^^
  File "/usr/local/lib/python3.11/site-packages/django/template/loader.py", line 62, in render_to_string
    return template.render(context, request)
           ^^^^^^^^^^^^^^^^^^^^^^^^^^^^^^^^^
  File "/usr/local/lib/python3.11/site-packages/django/template/backends/django.py", line 61, in render
    return self.template.render(context)
           ^^^^^^^^^^^^^^^^^^^^^^^^^^^^^
  File "/usr/local/lib/python3.11/site-packages/django/template/base.py", line 175, in render
    return self._render(context)
           ^^^^^^^^^^^^^^^^^^^^^
  File "/usr/local/lib/python3.11/site-packages/django/template/base.py", line 167, in _render
    return self.nodelist.render(context)
           ^^^^^^^^^^^^^^^^^^^^^^^^^^^^^
  File "/usr/local/lib/python3.11/site-packages/django/template/base.py", line 1005, in render
    return SafeString("".join([node.render_annotated(context) for node in self]))
                              ^^^^^^^^^^^^^^^^^^^^^^^^^^^^^^^^^^^^^^^^^^^^^^^^^
  File "/usr/local/lib/python3.11/site-packages/django/template/base.py", line 1005, in <listcomp>
    return SafeString("".join([node.render_annotated(context) for node in self]))
                               ^^^^^^^^^^^^^^^^^^^^^^^^^^^^^^
  File "/usr/local/lib/python3.11/site-packages/django/template/base.py", line 966, in render_annotated
    return self.render(context)
           ^^^^^^^^^^^^^^^^^^^^
  File "/usr/local/lib/python3.11/site-packages/django/template/loader_tags.py", line 157, in render
    return compiled_parent._render(context)
           ^^^^^^^^^^^^^^^^^^^^^^^^^^^^^^^^
  File "/usr/local/lib/python3.11/site-packages/django/template/base.py", line 167, in _render
    return self.nodelist.render(context)
           ^^^^^^^^^^^^^^^^^^^^^^^^^^^^^
  File "/usr/local/lib/python3.11/site-packages/django/template/base.py", line 1005, in render
    return SafeString("".join([node.render_annotated(context) for node in self]))
                              ^^^^^^^^^^^^^^^^^^^^^^^^^^^^^^^^^^^^^^^^^^^^^^^^^
  File "/usr/local/lib/python3.11/site-packages/django/template/base.py", line 1005, in <listcomp>
    return SafeString("".join([node.render_annotated(context) for node in self]))
                               ^^^^^^^^^^^^^^^^^^^^^^^^^^^^^^
  File "/usr/local/lib/python3.11/site-packages/django/template/base.py", line 966, in render_annotated
    return self.render(context)
           ^^^^^^^^^^^^^^^^^^^^
  File "/usr/local/lib/python3.11/site-packages/django/template/loader_tags.py", line 63, in render
    result = block.nodelist.render(context)
             ^^^^^^^^^^^^^^^^^^^^^^^^^^^^^^
  File "/usr/local/lib/python3.11/site-packages/django/template/base.py", line 1005, in render
    return SafeString("".join([node.render_annotated(context) for node in self]))
                              ^^^^^^^^^^^^^^^^^^^^^^^^^^^^^^^^^^^^^^^^^^^^^^^^^
  File "/usr/local/lib/python3.11/site-packages/django/template/base.py", line 1005, in <listcomp>
    return SafeString("".join([node.render_annotated(context) for node in self]))
                               ^^^^^^^^^^^^^^^^^^^^^^^^^^^^^^
  File "/usr/local/lib/python3.11/site-packages/django/template/base.py", line 966, in render_annotated
    return self.render(context)
           ^^^^^^^^^^^^^^^^^^^^
  File "/usr/local/lib/python3.11/site-packages/django/template/base.py", line 1064, in render
    output = self.filter_expression.resolve(context)
             ^^^^^^^^^^^^^^^^^^^^^^^^^^^^^^^^^^^^^^^
  File "/usr/local/lib/python3.11/site-packages/django/template/base.py", line 715, in resolve
    obj = self.var.resolve(context)
          ^^^^^^^^^^^^^^^^^^^^^^^^^
  File "/usr/local/lib/python3.11/site-packages/django/template/base.py", line 847, in resolve
    value = self._resolve_lookup(context)
            ^^^^^^^^^^^^^^^^^^^^^^^^^^^^^
  File "/usr/local/lib/python3.11/site-packages/django/template/base.py", line 914, in _resolve_lookup
    current = current()
              ^^^^^^^^^
  File "/usr/local/lib/python3.11/site-packages/django/forms/utils.py", line 88, in as_table
    return self.render(self.template_name_table)
           ^^^^^^^^^^^^^^^^^^^^^^^^^^^^^^^^^^^^^
  File "/usr/local/lib/python3.11/site-packages/django/forms/utils.py", line 67, in render
    context = context or self.get_context()
                         ^^^^^^^^^^^^^^^^^^
  File "/usr/local/lib/python3.11/site-packages/django/forms/forms.py", line 322, in get_context
    top_errors = self.non_field_errors().copy()
                 ^^^^^^^^^^^^^^^^^^^^^^^
  File "/usr/local/lib/python3.11/site-packages/django/forms/forms.py", line 358, in non_field_errors
    return self.errors.get(
           ^^^^^^^^^^^
  File "/usr/local/lib/python3.11/site-packages/django/forms/forms.py", line 196, in errors
    self.full_clean()
  File "/usr/local/lib/python3.11/site-packages/django/forms/forms.py", line 433, in full_clean
    self._clean_fields()
  File "/usr/local/lib/python3.11/site-packages/django/forms/forms.py", line 440, in _clean_fields
    value = bf.initial if field.disabled else bf.data
                                              ^^^^^^^
  File "/usr/local/lib/python3.11/site-packages/django/forms/boundfield.py", line 135, in data
    return self.form._widget_data_value(self.field.widget, self.html_name)
           ^^^^^^^^^^^^^^^^^^^^^^^^^^^^^^^^^^^^^^^^^^^^^^^^^^^^^^^^^^^^^^^
  File "/usr/local/lib/python3.11/site-packages/django/forms/forms.py", line 220, in _widget_data_value
    return widget.value_from_datadict(self.data, self.files, html_name)
           ^^^^^^^^^^^^^^^^^^^^^^^^^^^^^^^^^^^^^^^^^^^^^^^^^^^^^^^^^^^^
  File "/usr/local/lib/python3.11/site-packages/django/forms/widgets.py", line 297, in value_from_datadict
    return data.get(name)
           ^^^^^^^^
  File "/usr/local/lib/python3.11/site-packages/django/utils/functional.py", line 268, in inner
    return func(_wrapped, *args)
           ^^^^^^^^^^^^^^^^^^^^^
AttributeError: 'User' object has no attribute 'get'
"GET /create/ HTTP/1.1" 500 203409
Internal Server Error: /todo_category/
Traceback (most recent call last):
  File "/usr/local/lib/python3.11/site-packages/django/core/handlers/exception.py", line 55, in inner
    response = get_response(request)
               ^^^^^^^^^^^^^^^^^^^^^
  File "/usr/local/lib/python3.11/site-packages/django/core/handlers/base.py", line 220, in _get_response
    response = response.render()
               ^^^^^^^^^^^^^^^^^
  File "/usr/local/lib/python3.11/site-packages/django/template/response.py", line 114, in render
    self.content = self.rendered_content
                   ^^^^^^^^^^^^^^^^^^^^^
  File "/usr/local/lib/python3.11/site-packages/django/template/response.py", line 90, in rendered_content
    template = self.resolve_template(self.template_name)
               ^^^^^^^^^^^^^^^^^^^^^^^^^^^^^^^^^^^^^^^^^
  File "/usr/local/lib/python3.11/site-packages/django/template/response.py", line 72, in resolve_template
    return select_template(template, using=self.using)
           ^^^^^^^^^^^^^^^^^^^^^^^^^^^^^^^^^^^^^^^^^^^
  File "/usr/local/lib/python3.11/site-packages/django/template/loader.py", line 42, in select_template
    return engine.get_template(template_name)
           ^^^^^^^^^^^^^^^^^^^^^^^^^^^^^^^^^^
  File "/usr/local/lib/python3.11/site-packages/django/template/backends/django.py", line 33, in get_template
    return Template(self.engine.get_template(template_name), self)
                    ^^^^^^^^^^^^^^^^^^^^^^^^^^^^^^^^^^^^^^^
  File "/usr/local/lib/python3.11/site-packages/django/template/engine.py", line 175, in get_template
    template, origin = self.find_template(template_name)
                       ^^^^^^^^^^^^^^^^^^^^^^^^^^^^^^^^^
  File "/usr/local/lib/python3.11/site-packages/django/template/engine.py", line 157, in find_template
    template = loader.get_template(name, skip=skip)
               ^^^^^^^^^^^^^^^^^^^^^^^^^^^^^^^^^^^^
  File "/usr/local/lib/python3.11/site-packages/django/template/loaders/cached.py", line 57, in get_template
    template = super().get_template(template_name, skip)
               ^^^^^^^^^^^^^^^^^^^^^^^^^^^^^^^^^^^^^^^^^
  File "/usr/local/lib/python3.11/site-packages/django/template/loaders/base.py", line 28, in get_template
    return Template(
           ^^^^^^^^^
  File "/usr/local/lib/python3.11/site-packages/django/template/base.py", line 154, in __init__
    self.nodelist = self.compile_nodelist()
                    ^^^^^^^^^^^^^^^^^^^^^^^
  File "/usr/local/lib/python3.11/site-packages/django/template/base.py", line 200, in compile_nodelist
    return parser.parse()
           ^^^^^^^^^^^^^^
  File "/usr/local/lib/python3.11/site-packages/django/template/base.py", line 514, in parse
    self.extend_nodelist(nodelist, compiled_result, token)
  File "/usr/local/lib/python3.11/site-packages/django/template/base.py", line 531, in extend_nodelist
    raise self.error(
django.template.exceptions.TemplateSyntaxError: <ExtendsNode: extends 'base.html'> must be the first tag in the template.
"GET /todo_category/ HTTP/1.1" 500 142116
Internal Server Error: /todo_category/
Traceback (most recent call last):
  File "/usr/local/lib/python3.11/site-packages/django/core/handlers/exception.py", line 55, in inner
    response = get_response(request)
               ^^^^^^^^^^^^^^^^^^^^^
  File "/usr/local/lib/python3.11/site-packages/django/core/handlers/base.py", line 220, in _get_response
    response = response.render()
               ^^^^^^^^^^^^^^^^^
  File "/usr/local/lib/python3.11/site-packages/django/template/response.py", line 114, in render
    self.content = self.rendered_content
                   ^^^^^^^^^^^^^^^^^^^^^
  File "/usr/local/lib/python3.11/site-packages/django/template/response.py", line 90, in rendered_content
    template = self.resolve_template(self.template_name)
               ^^^^^^^^^^^^^^^^^^^^^^^^^^^^^^^^^^^^^^^^^
  File "/usr/local/lib/python3.11/site-packages/django/template/response.py", line 72, in resolve_template
    return select_template(template, using=self.using)
           ^^^^^^^^^^^^^^^^^^^^^^^^^^^^^^^^^^^^^^^^^^^
  File "/usr/local/lib/python3.11/site-packages/django/template/loader.py", line 42, in select_template
    return engine.get_template(template_name)
           ^^^^^^^^^^^^^^^^^^^^^^^^^^^^^^^^^^
  File "/usr/local/lib/python3.11/site-packages/django/template/backends/django.py", line 33, in get_template
    return Template(self.engine.get_template(template_name), self)
                    ^^^^^^^^^^^^^^^^^^^^^^^^^^^^^^^^^^^^^^^
  File "/usr/local/lib/python3.11/site-packages/django/template/engine.py", line 175, in get_template
    template, origin = self.find_template(template_name)
                       ^^^^^^^^^^^^^^^^^^^^^^^^^^^^^^^^^
  File "/usr/local/lib/python3.11/site-packages/django/template/engine.py", line 157, in find_template
    template = loader.get_template(name, skip=skip)
               ^^^^^^^^^^^^^^^^^^^^^^^^^^^^^^^^^^^^
  File "/usr/local/lib/python3.11/site-packages/django/template/loaders/cached.py", line 57, in get_template
    template = super().get_template(template_name, skip)
               ^^^^^^^^^^^^^^^^^^^^^^^^^^^^^^^^^^^^^^^^^
  File "/usr/local/lib/python3.11/site-packages/django/template/loaders/base.py", line 28, in get_template
    return Template(
           ^^^^^^^^^
  File "/usr/local/lib/python3.11/site-packages/django/template/base.py", line 154, in __init__
    self.nodelist = self.compile_nodelist()
                    ^^^^^^^^^^^^^^^^^^^^^^^
  File "/usr/local/lib/python3.11/site-packages/django/template/base.py", line 200, in compile_nodelist
    return parser.parse()
           ^^^^^^^^^^^^^^
  File "/usr/local/lib/python3.11/site-packages/django/template/base.py", line 514, in parse
    self.extend_nodelist(nodelist, compiled_result, token)
  File "/usr/local/lib/python3.11/site-packages/django/template/base.py", line 531, in extend_nodelist
    raise self.error(
django.template.exceptions.TemplateSyntaxError: <ExtendsNode: extends 'base.html'> must be the first tag in the template.
"GET /todo_category/ HTTP/1.1" 500 141960
Internal Server Error: /todo_category/
Traceback (most recent call last):
  File "/usr/local/lib/python3.11/site-packages/django/core/handlers/exception.py", line 55, in inner
    response = get_response(request)
               ^^^^^^^^^^^^^^^^^^^^^
  File "/usr/local/lib/python3.11/site-packages/django/core/handlers/base.py", line 220, in _get_response
    response = response.render()
               ^^^^^^^^^^^^^^^^^
  File "/usr/local/lib/python3.11/site-packages/django/template/response.py", line 114, in render
    self.content = self.rendered_content
                   ^^^^^^^^^^^^^^^^^^^^^
  File "/usr/local/lib/python3.11/site-packages/django/template/response.py", line 90, in rendered_content
    template = self.resolve_template(self.template_name)
               ^^^^^^^^^^^^^^^^^^^^^^^^^^^^^^^^^^^^^^^^^
  File "/usr/local/lib/python3.11/site-packages/django/template/response.py", line 72, in resolve_template
    return select_template(template, using=self.using)
           ^^^^^^^^^^^^^^^^^^^^^^^^^^^^^^^^^^^^^^^^^^^
  File "/usr/local/lib/python3.11/site-packages/django/template/loader.py", line 42, in select_template
    return engine.get_template(template_name)
           ^^^^^^^^^^^^^^^^^^^^^^^^^^^^^^^^^^
  File "/usr/local/lib/python3.11/site-packages/django/template/backends/django.py", line 33, in get_template
    return Template(self.engine.get_template(template_name), self)
                    ^^^^^^^^^^^^^^^^^^^^^^^^^^^^^^^^^^^^^^^
  File "/usr/local/lib/python3.11/site-packages/django/template/engine.py", line 175, in get_template
    template, origin = self.find_template(template_name)
                       ^^^^^^^^^^^^^^^^^^^^^^^^^^^^^^^^^
  File "/usr/local/lib/python3.11/site-packages/django/template/engine.py", line 157, in find_template
    template = loader.get_template(name, skip=skip)
               ^^^^^^^^^^^^^^^^^^^^^^^^^^^^^^^^^^^^
  File "/usr/local/lib/python3.11/site-packages/django/template/loaders/cached.py", line 57, in get_template
    template = super().get_template(template_name, skip)
               ^^^^^^^^^^^^^^^^^^^^^^^^^^^^^^^^^^^^^^^^^
  File "/usr/local/lib/python3.11/site-packages/django/template/loaders/base.py", line 28, in get_template
    return Template(
           ^^^^^^^^^
  File "/usr/local/lib/python3.11/site-packages/django/template/base.py", line 154, in __init__
    self.nodelist = self.compile_nodelist()
                    ^^^^^^^^^^^^^^^^^^^^^^^
  File "/usr/local/lib/python3.11/site-packages/django/template/base.py", line 200, in compile_nodelist
    return parser.parse()
           ^^^^^^^^^^^^^^
  File "/usr/local/lib/python3.11/site-packages/django/template/base.py", line 514, in parse
    self.extend_nodelist(nodelist, compiled_result, token)
  File "/usr/local/lib/python3.11/site-packages/django/template/base.py", line 531, in extend_nodelist
    raise self.error(
django.template.exceptions.TemplateSyntaxError: <ExtendsNode: extends 'base.html'> must be the first tag in the template.
"GET /todo_category/ HTTP/1.1" 500 142116
Internal Server Error: /todo_category/
Traceback (most recent call last):
  File "/usr/local/lib/python3.11/site-packages/django/template/base.py", line 505, in parse
    compile_func = self.tags[command]
                   ~~~~~~~~~^^^^^^^^^
KeyError: 'endblock'

During handling of the above exception, another exception occurred:

Traceback (most recent call last):
  File "/usr/local/lib/python3.11/site-packages/django/core/handlers/exception.py", line 55, in inner
    response = get_response(request)
               ^^^^^^^^^^^^^^^^^^^^^
  File "/usr/local/lib/python3.11/site-packages/django/core/handlers/base.py", line 220, in _get_response
    response = response.render()
               ^^^^^^^^^^^^^^^^^
  File "/usr/local/lib/python3.11/site-packages/django/template/response.py", line 114, in render
    self.content = self.rendered_content
                   ^^^^^^^^^^^^^^^^^^^^^
  File "/usr/local/lib/python3.11/site-packages/django/template/response.py", line 90, in rendered_content
    template = self.resolve_template(self.template_name)
               ^^^^^^^^^^^^^^^^^^^^^^^^^^^^^^^^^^^^^^^^^
  File "/usr/local/lib/python3.11/site-packages/django/template/response.py", line 72, in resolve_template
    return select_template(template, using=self.using)
           ^^^^^^^^^^^^^^^^^^^^^^^^^^^^^^^^^^^^^^^^^^^
  File "/usr/local/lib/python3.11/site-packages/django/template/loader.py", line 42, in select_template
    return engine.get_template(template_name)
           ^^^^^^^^^^^^^^^^^^^^^^^^^^^^^^^^^^
  File "/usr/local/lib/python3.11/site-packages/django/template/backends/django.py", line 33, in get_template
    return Template(self.engine.get_template(template_name), self)
                    ^^^^^^^^^^^^^^^^^^^^^^^^^^^^^^^^^^^^^^^
  File "/usr/local/lib/python3.11/site-packages/django/template/engine.py", line 175, in get_template
    template, origin = self.find_template(template_name)
                       ^^^^^^^^^^^^^^^^^^^^^^^^^^^^^^^^^
  File "/usr/local/lib/python3.11/site-packages/django/template/engine.py", line 157, in find_template
    template = loader.get_template(name, skip=skip)
               ^^^^^^^^^^^^^^^^^^^^^^^^^^^^^^^^^^^^
  File "/usr/local/lib/python3.11/site-packages/django/template/loaders/cached.py", line 57, in get_template
    template = super().get_template(template_name, skip)
               ^^^^^^^^^^^^^^^^^^^^^^^^^^^^^^^^^^^^^^^^^
  File "/usr/local/lib/python3.11/site-packages/django/template/loaders/base.py", line 28, in get_template
    return Template(
           ^^^^^^^^^
  File "/usr/local/lib/python3.11/site-packages/django/template/base.py", line 154, in __init__
    self.nodelist = self.compile_nodelist()
                    ^^^^^^^^^^^^^^^^^^^^^^^
  File "/usr/local/lib/python3.11/site-packages/django/template/base.py", line 200, in compile_nodelist
    return parser.parse()
           ^^^^^^^^^^^^^^
  File "/usr/local/lib/python3.11/site-packages/django/template/base.py", line 513, in parse
    raise self.error(token, e)
  File "/usr/local/lib/python3.11/site-packages/django/template/base.py", line 511, in parse
    compiled_result = compile_func(self, token)
                      ^^^^^^^^^^^^^^^^^^^^^^^^^
  File "/usr/local/lib/python3.11/site-packages/django/template/loader_tags.py", line 232, in do_block
    nodelist = parser.parse(("endblock",))
               ^^^^^^^^^^^^^^^^^^^^^^^^^^^
  File "/usr/local/lib/python3.11/site-packages/django/template/base.py", line 513, in parse
    raise self.error(token, e)
  File "/usr/local/lib/python3.11/site-packages/django/template/base.py", line 511, in parse
    compiled_result = compile_func(self, token)
                      ^^^^^^^^^^^^^^^^^^^^^^^^^
  File "/usr/local/lib/python3.11/site-packages/django/template/loader_tags.py", line 293, in do_extends
    nodelist = parser.parse()
               ^^^^^^^^^^^^^^
  File "/usr/local/lib/python3.11/site-packages/django/template/base.py", line 507, in parse
    self.invalid_block_tag(token, command, parse_until)
  File "/usr/local/lib/python3.11/site-packages/django/template/base.py", line 568, in invalid_block_tag
    raise self.error(
django.template.exceptions.TemplateSyntaxError: Invalid block tag on line 113: 'endblock'. Did you forget to register or load this tag?
"GET /todo_category/ HTTP/1.1" 500 176217
Internal Server Error: /create/
Traceback (most recent call last):
  File "/usr/local/lib/python3.11/site-packages/django/core/handlers/exception.py", line 55, in inner
    response = get_response(request)
               ^^^^^^^^^^^^^^^^^^^^^
  File "/usr/local/lib/python3.11/site-packages/django/core/handlers/base.py", line 197, in _get_response
    response = wrapped_callback(request, *callback_args, **callback_kwargs)
               ^^^^^^^^^^^^^^^^^^^^^^^^^^^^^^^^^^^^^^^^^^^^^^^^^^^^^^^^^^^^
  File "/usr/local/lib/python3.11/site-packages/django/contrib/auth/decorators.py", line 23, in _wrapper_view
    return view_func(request, *args, **kwargs)
           ^^^^^^^^^^^^^^^^^^^^^^^^^^^^^^^^^^^
  File "/Users/taramanjimacbookpro/Documents/GitHub/OpenHackU2023_Ritskomachi/todo/views.py", line 149, in create_todo
    return render(request, 'todo/todo_form.html', {'form': form})
           ^^^^^^^^^^^^^^^^^^^^^^^^^^^^^^^^^^^^^^^^^^^^^^^^^^^^^^
  File "/usr/local/lib/python3.11/site-packages/django/shortcuts.py", line 24, in render
    content = loader.render_to_string(template_name, context, request, using=using)
              ^^^^^^^^^^^^^^^^^^^^^^^^^^^^^^^^^^^^^^^^^^^^^^^^^^^^^^^^^^^^^^^^^^^^^
  File "/usr/local/lib/python3.11/site-packages/django/template/loader.py", line 62, in render_to_string
    return template.render(context, request)
           ^^^^^^^^^^^^^^^^^^^^^^^^^^^^^^^^^
  File "/usr/local/lib/python3.11/site-packages/django/template/backends/django.py", line 61, in render
    return self.template.render(context)
           ^^^^^^^^^^^^^^^^^^^^^^^^^^^^^
  File "/usr/local/lib/python3.11/site-packages/django/template/base.py", line 175, in render
    return self._render(context)
           ^^^^^^^^^^^^^^^^^^^^^
  File "/usr/local/lib/python3.11/site-packages/django/template/base.py", line 167, in _render
    return self.nodelist.render(context)
           ^^^^^^^^^^^^^^^^^^^^^^^^^^^^^
  File "/usr/local/lib/python3.11/site-packages/django/template/base.py", line 1005, in render
    return SafeString("".join([node.render_annotated(context) for node in self]))
                              ^^^^^^^^^^^^^^^^^^^^^^^^^^^^^^^^^^^^^^^^^^^^^^^^^
  File "/usr/local/lib/python3.11/site-packages/django/template/base.py", line 1005, in <listcomp>
    return SafeString("".join([node.render_annotated(context) for node in self]))
                               ^^^^^^^^^^^^^^^^^^^^^^^^^^^^^^
  File "/usr/local/lib/python3.11/site-packages/django/template/base.py", line 966, in render_annotated
    return self.render(context)
           ^^^^^^^^^^^^^^^^^^^^
  File "/usr/local/lib/python3.11/site-packages/django/template/loader_tags.py", line 157, in render
    return compiled_parent._render(context)
           ^^^^^^^^^^^^^^^^^^^^^^^^^^^^^^^^
  File "/usr/local/lib/python3.11/site-packages/django/template/base.py", line 167, in _render
    return self.nodelist.render(context)
           ^^^^^^^^^^^^^^^^^^^^^^^^^^^^^
  File "/usr/local/lib/python3.11/site-packages/django/template/base.py", line 1005, in render
    return SafeString("".join([node.render_annotated(context) for node in self]))
                              ^^^^^^^^^^^^^^^^^^^^^^^^^^^^^^^^^^^^^^^^^^^^^^^^^
  File "/usr/local/lib/python3.11/site-packages/django/template/base.py", line 1005, in <listcomp>
    return SafeString("".join([node.render_annotated(context) for node in self]))
                               ^^^^^^^^^^^^^^^^^^^^^^^^^^^^^^
  File "/usr/local/lib/python3.11/site-packages/django/template/base.py", line 966, in render_annotated
    return self.render(context)
           ^^^^^^^^^^^^^^^^^^^^
  File "/usr/local/lib/python3.11/site-packages/django/template/loader_tags.py", line 63, in render
    result = block.nodelist.render(context)
             ^^^^^^^^^^^^^^^^^^^^^^^^^^^^^^
  File "/usr/local/lib/python3.11/site-packages/django/template/base.py", line 1005, in render
    return SafeString("".join([node.render_annotated(context) for node in self]))
                              ^^^^^^^^^^^^^^^^^^^^^^^^^^^^^^^^^^^^^^^^^^^^^^^^^
  File "/usr/local/lib/python3.11/site-packages/django/template/base.py", line 1005, in <listcomp>
    return SafeString("".join([node.render_annotated(context) for node in self]))
                               ^^^^^^^^^^^^^^^^^^^^^^^^^^^^^^
  File "/usr/local/lib/python3.11/site-packages/django/template/base.py", line 966, in render_annotated
    return self.render(context)
           ^^^^^^^^^^^^^^^^^^^^
  File "/usr/local/lib/python3.11/site-packages/django/template/base.py", line 1064, in render
    output = self.filter_expression.resolve(context)
             ^^^^^^^^^^^^^^^^^^^^^^^^^^^^^^^^^^^^^^^
  File "/usr/local/lib/python3.11/site-packages/django/template/base.py", line 715, in resolve
    obj = self.var.resolve(context)
          ^^^^^^^^^^^^^^^^^^^^^^^^^
  File "/usr/local/lib/python3.11/site-packages/django/template/base.py", line 847, in resolve
    value = self._resolve_lookup(context)
            ^^^^^^^^^^^^^^^^^^^^^^^^^^^^^
  File "/usr/local/lib/python3.11/site-packages/django/template/base.py", line 914, in _resolve_lookup
    current = current()
              ^^^^^^^^^
  File "/usr/local/lib/python3.11/site-packages/django/forms/utils.py", line 88, in as_table
    return self.render(self.template_name_table)
           ^^^^^^^^^^^^^^^^^^^^^^^^^^^^^^^^^^^^^
  File "/usr/local/lib/python3.11/site-packages/django/forms/utils.py", line 67, in render
    context = context or self.get_context()
                         ^^^^^^^^^^^^^^^^^^
  File "/usr/local/lib/python3.11/site-packages/django/forms/forms.py", line 322, in get_context
    top_errors = self.non_field_errors().copy()
                 ^^^^^^^^^^^^^^^^^^^^^^^
  File "/usr/local/lib/python3.11/site-packages/django/forms/forms.py", line 358, in non_field_errors
    return self.errors.get(
           ^^^^^^^^^^^
  File "/usr/local/lib/python3.11/site-packages/django/forms/forms.py", line 196, in errors
    self.full_clean()
  File "/usr/local/lib/python3.11/site-packages/django/forms/forms.py", line 433, in full_clean
    self._clean_fields()
  File "/usr/local/lib/python3.11/site-packages/django/forms/forms.py", line 440, in _clean_fields
    value = bf.initial if field.disabled else bf.data
                                              ^^^^^^^
  File "/usr/local/lib/python3.11/site-packages/django/forms/boundfield.py", line 135, in data
    return self.form._widget_data_value(self.field.widget, self.html_name)
           ^^^^^^^^^^^^^^^^^^^^^^^^^^^^^^^^^^^^^^^^^^^^^^^^^^^^^^^^^^^^^^^
  File "/usr/local/lib/python3.11/site-packages/django/forms/forms.py", line 220, in _widget_data_value
    return widget.value_from_datadict(self.data, self.files, html_name)
           ^^^^^^^^^^^^^^^^^^^^^^^^^^^^^^^^^^^^^^^^^^^^^^^^^^^^^^^^^^^^
  File "/usr/local/lib/python3.11/site-packages/django/forms/widgets.py", line 297, in value_from_datadict
    return data.get(name)
           ^^^^^^^^
  File "/usr/local/lib/python3.11/site-packages/django/utils/functional.py", line 268, in inner
    return func(_wrapped, *args)
           ^^^^^^^^^^^^^^^^^^^^^
AttributeError: 'User' object has no attribute 'get'
"GET /create/ HTTP/1.1" 500 203418
Internal Server Error: /create/
Traceback (most recent call last):
  File "/usr/local/lib/python3.11/site-packages/django/core/handlers/exception.py", line 55, in inner
    response = get_response(request)
               ^^^^^^^^^^^^^^^^^^^^^
  File "/usr/local/lib/python3.11/site-packages/django/core/handlers/base.py", line 197, in _get_response
    response = wrapped_callback(request, *callback_args, **callback_kwargs)
               ^^^^^^^^^^^^^^^^^^^^^^^^^^^^^^^^^^^^^^^^^^^^^^^^^^^^^^^^^^^^
  File "/usr/local/lib/python3.11/site-packages/django/contrib/auth/decorators.py", line 23, in _wrapper_view
    return view_func(request, *args, **kwargs)
           ^^^^^^^^^^^^^^^^^^^^^^^^^^^^^^^^^^^
  File "/Users/taramanjimacbookpro/Documents/GitHub/OpenHackU2023_Ritskomachi/todo/views.py", line 149, in create_todo
    return render(request, 'todo/todo_form.html', {'form': form})
           ^^^^^^^^^^^^^^^^^^^^^^^^^^^^^^^^^^^^^^^^^^^^^^^^^^^^^^
  File "/usr/local/lib/python3.11/site-packages/django/shortcuts.py", line 24, in render
    content = loader.render_to_string(template_name, context, request, using=using)
              ^^^^^^^^^^^^^^^^^^^^^^^^^^^^^^^^^^^^^^^^^^^^^^^^^^^^^^^^^^^^^^^^^^^^^
  File "/usr/local/lib/python3.11/site-packages/django/template/loader.py", line 62, in render_to_string
    return template.render(context, request)
           ^^^^^^^^^^^^^^^^^^^^^^^^^^^^^^^^^
  File "/usr/local/lib/python3.11/site-packages/django/template/backends/django.py", line 61, in render
    return self.template.render(context)
           ^^^^^^^^^^^^^^^^^^^^^^^^^^^^^
  File "/usr/local/lib/python3.11/site-packages/django/template/base.py", line 175, in render
    return self._render(context)
           ^^^^^^^^^^^^^^^^^^^^^
  File "/usr/local/lib/python3.11/site-packages/django/template/base.py", line 167, in _render
    return self.nodelist.render(context)
           ^^^^^^^^^^^^^^^^^^^^^^^^^^^^^
  File "/usr/local/lib/python3.11/site-packages/django/template/base.py", line 1005, in render
    return SafeString("".join([node.render_annotated(context) for node in self]))
                              ^^^^^^^^^^^^^^^^^^^^^^^^^^^^^^^^^^^^^^^^^^^^^^^^^
  File "/usr/local/lib/python3.11/site-packages/django/template/base.py", line 1005, in <listcomp>
    return SafeString("".join([node.render_annotated(context) for node in self]))
                               ^^^^^^^^^^^^^^^^^^^^^^^^^^^^^^
  File "/usr/local/lib/python3.11/site-packages/django/template/base.py", line 966, in render_annotated
    return self.render(context)
           ^^^^^^^^^^^^^^^^^^^^
  File "/usr/local/lib/python3.11/site-packages/django/template/loader_tags.py", line 157, in render
    return compiled_parent._render(context)
           ^^^^^^^^^^^^^^^^^^^^^^^^^^^^^^^^
  File "/usr/local/lib/python3.11/site-packages/django/template/base.py", line 167, in _render
    return self.nodelist.render(context)
           ^^^^^^^^^^^^^^^^^^^^^^^^^^^^^
  File "/usr/local/lib/python3.11/site-packages/django/template/base.py", line 1005, in render
    return SafeString("".join([node.render_annotated(context) for node in self]))
                              ^^^^^^^^^^^^^^^^^^^^^^^^^^^^^^^^^^^^^^^^^^^^^^^^^
  File "/usr/local/lib/python3.11/site-packages/django/template/base.py", line 1005, in <listcomp>
    return SafeString("".join([node.render_annotated(context) for node in self]))
                               ^^^^^^^^^^^^^^^^^^^^^^^^^^^^^^
  File "/usr/local/lib/python3.11/site-packages/django/template/base.py", line 966, in render_annotated
    return self.render(context)
           ^^^^^^^^^^^^^^^^^^^^
  File "/usr/local/lib/python3.11/site-packages/django/template/loader_tags.py", line 63, in render
    result = block.nodelist.render(context)
             ^^^^^^^^^^^^^^^^^^^^^^^^^^^^^^
  File "/usr/local/lib/python3.11/site-packages/django/template/base.py", line 1005, in render
    return SafeString("".join([node.render_annotated(context) for node in self]))
                              ^^^^^^^^^^^^^^^^^^^^^^^^^^^^^^^^^^^^^^^^^^^^^^^^^
  File "/usr/local/lib/python3.11/site-packages/django/template/base.py", line 1005, in <listcomp>
    return SafeString("".join([node.render_annotated(context) for node in self]))
                               ^^^^^^^^^^^^^^^^^^^^^^^^^^^^^^
  File "/usr/local/lib/python3.11/site-packages/django/template/base.py", line 966, in render_annotated
    return self.render(context)
           ^^^^^^^^^^^^^^^^^^^^
  File "/usr/local/lib/python3.11/site-packages/django/template/base.py", line 1064, in render
    output = self.filter_expression.resolve(context)
             ^^^^^^^^^^^^^^^^^^^^^^^^^^^^^^^^^^^^^^^
  File "/usr/local/lib/python3.11/site-packages/django/template/base.py", line 715, in resolve
    obj = self.var.resolve(context)
          ^^^^^^^^^^^^^^^^^^^^^^^^^
  File "/usr/local/lib/python3.11/site-packages/django/template/base.py", line 847, in resolve
    value = self._resolve_lookup(context)
            ^^^^^^^^^^^^^^^^^^^^^^^^^^^^^
  File "/usr/local/lib/python3.11/site-packages/django/template/base.py", line 914, in _resolve_lookup
    current = current()
              ^^^^^^^^^
  File "/usr/local/lib/python3.11/site-packages/django/forms/utils.py", line 88, in as_table
    return self.render(self.template_name_table)
           ^^^^^^^^^^^^^^^^^^^^^^^^^^^^^^^^^^^^^
  File "/usr/local/lib/python3.11/site-packages/django/forms/utils.py", line 67, in render
    context = context or self.get_context()
                         ^^^^^^^^^^^^^^^^^^
  File "/usr/local/lib/python3.11/site-packages/django/forms/forms.py", line 322, in get_context
    top_errors = self.non_field_errors().copy()
                 ^^^^^^^^^^^^^^^^^^^^^^^
  File "/usr/local/lib/python3.11/site-packages/django/forms/forms.py", line 358, in non_field_errors
    return self.errors.get(
           ^^^^^^^^^^^
  File "/usr/local/lib/python3.11/site-packages/django/forms/forms.py", line 196, in errors
    self.full_clean()
  File "/usr/local/lib/python3.11/site-packages/django/forms/forms.py", line 433, in full_clean
    self._clean_fields()
  File "/usr/local/lib/python3.11/site-packages/django/forms/forms.py", line 440, in _clean_fields
    value = bf.initial if field.disabled else bf.data
                                              ^^^^^^^
  File "/usr/local/lib/python3.11/site-packages/django/forms/boundfield.py", line 135, in data
    return self.form._widget_data_value(self.field.widget, self.html_name)
           ^^^^^^^^^^^^^^^^^^^^^^^^^^^^^^^^^^^^^^^^^^^^^^^^^^^^^^^^^^^^^^^
  File "/usr/local/lib/python3.11/site-packages/django/forms/forms.py", line 220, in _widget_data_value
    return widget.value_from_datadict(self.data, self.files, html_name)
           ^^^^^^^^^^^^^^^^^^^^^^^^^^^^^^^^^^^^^^^^^^^^^^^^^^^^^^^^^^^^
  File "/usr/local/lib/python3.11/site-packages/django/forms/widgets.py", line 297, in value_from_datadict
    return data.get(name)
           ^^^^^^^^
  File "/usr/local/lib/python3.11/site-packages/django/utils/functional.py", line 268, in inner
    return func(_wrapped, *args)
           ^^^^^^^^^^^^^^^^^^^^^
AttributeError: 'User' object has no attribute 'get'
"GET /create/ HTTP/1.1" 500 203253
Internal Server Error: /create/
Traceback (most recent call last):
  File "/usr/local/lib/python3.11/site-packages/django/core/handlers/exception.py", line 55, in inner
    response = get_response(request)
               ^^^^^^^^^^^^^^^^^^^^^
  File "/usr/local/lib/python3.11/site-packages/django/core/handlers/base.py", line 197, in _get_response
    response = wrapped_callback(request, *callback_args, **callback_kwargs)
               ^^^^^^^^^^^^^^^^^^^^^^^^^^^^^^^^^^^^^^^^^^^^^^^^^^^^^^^^^^^^
  File "/usr/local/lib/python3.11/site-packages/django/contrib/auth/decorators.py", line 23, in _wrapper_view
    return view_func(request, *args, **kwargs)
           ^^^^^^^^^^^^^^^^^^^^^^^^^^^^^^^^^^^
  File "/Users/taramanjimacbookpro/Documents/GitHub/OpenHackU2023_Ritskomachi/todo/views.py", line 148, in create_todo
    return render(request, 'todo/todo_form.html', {'form': form})
           ^^^^^^^^^^^^^^^^^^^^^^^^^^^^^^^^^^^^^^^^^^^^^^^^^^^^^^
  File "/usr/local/lib/python3.11/site-packages/django/shortcuts.py", line 24, in render
    content = loader.render_to_string(template_name, context, request, using=using)
              ^^^^^^^^^^^^^^^^^^^^^^^^^^^^^^^^^^^^^^^^^^^^^^^^^^^^^^^^^^^^^^^^^^^^^
  File "/usr/local/lib/python3.11/site-packages/django/template/loader.py", line 62, in render_to_string
    return template.render(context, request)
           ^^^^^^^^^^^^^^^^^^^^^^^^^^^^^^^^^
  File "/usr/local/lib/python3.11/site-packages/django/template/backends/django.py", line 61, in render
    return self.template.render(context)
           ^^^^^^^^^^^^^^^^^^^^^^^^^^^^^
  File "/usr/local/lib/python3.11/site-packages/django/template/base.py", line 175, in render
    return self._render(context)
           ^^^^^^^^^^^^^^^^^^^^^
  File "/usr/local/lib/python3.11/site-packages/django/template/base.py", line 167, in _render
    return self.nodelist.render(context)
           ^^^^^^^^^^^^^^^^^^^^^^^^^^^^^
  File "/usr/local/lib/python3.11/site-packages/django/template/base.py", line 1005, in render
    return SafeString("".join([node.render_annotated(context) for node in self]))
                              ^^^^^^^^^^^^^^^^^^^^^^^^^^^^^^^^^^^^^^^^^^^^^^^^^
  File "/usr/local/lib/python3.11/site-packages/django/template/base.py", line 1005, in <listcomp>
    return SafeString("".join([node.render_annotated(context) for node in self]))
                               ^^^^^^^^^^^^^^^^^^^^^^^^^^^^^^
  File "/usr/local/lib/python3.11/site-packages/django/template/base.py", line 966, in render_annotated
    return self.render(context)
           ^^^^^^^^^^^^^^^^^^^^
  File "/usr/local/lib/python3.11/site-packages/django/template/loader_tags.py", line 157, in render
    return compiled_parent._render(context)
           ^^^^^^^^^^^^^^^^^^^^^^^^^^^^^^^^
  File "/usr/local/lib/python3.11/site-packages/django/template/base.py", line 167, in _render
    return self.nodelist.render(context)
           ^^^^^^^^^^^^^^^^^^^^^^^^^^^^^
  File "/usr/local/lib/python3.11/site-packages/django/template/base.py", line 1005, in render
    return SafeString("".join([node.render_annotated(context) for node in self]))
                              ^^^^^^^^^^^^^^^^^^^^^^^^^^^^^^^^^^^^^^^^^^^^^^^^^
  File "/usr/local/lib/python3.11/site-packages/django/template/base.py", line 1005, in <listcomp>
    return SafeString("".join([node.render_annotated(context) for node in self]))
                               ^^^^^^^^^^^^^^^^^^^^^^^^^^^^^^
  File "/usr/local/lib/python3.11/site-packages/django/template/base.py", line 966, in render_annotated
    return self.render(context)
           ^^^^^^^^^^^^^^^^^^^^
  File "/usr/local/lib/python3.11/site-packages/django/template/loader_tags.py", line 63, in render
    result = block.nodelist.render(context)
             ^^^^^^^^^^^^^^^^^^^^^^^^^^^^^^
  File "/usr/local/lib/python3.11/site-packages/django/template/base.py", line 1005, in render
    return SafeString("".join([node.render_annotated(context) for node in self]))
                              ^^^^^^^^^^^^^^^^^^^^^^^^^^^^^^^^^^^^^^^^^^^^^^^^^
  File "/usr/local/lib/python3.11/site-packages/django/template/base.py", line 1005, in <listcomp>
    return SafeString("".join([node.render_annotated(context) for node in self]))
                               ^^^^^^^^^^^^^^^^^^^^^^^^^^^^^^
  File "/usr/local/lib/python3.11/site-packages/django/template/base.py", line 966, in render_annotated
    return self.render(context)
           ^^^^^^^^^^^^^^^^^^^^
  File "/usr/local/lib/python3.11/site-packages/django/template/base.py", line 1064, in render
    output = self.filter_expression.resolve(context)
             ^^^^^^^^^^^^^^^^^^^^^^^^^^^^^^^^^^^^^^^
  File "/usr/local/lib/python3.11/site-packages/django/template/base.py", line 715, in resolve
    obj = self.var.resolve(context)
          ^^^^^^^^^^^^^^^^^^^^^^^^^
  File "/usr/local/lib/python3.11/site-packages/django/template/base.py", line 847, in resolve
    value = self._resolve_lookup(context)
            ^^^^^^^^^^^^^^^^^^^^^^^^^^^^^
  File "/usr/local/lib/python3.11/site-packages/django/template/base.py", line 914, in _resolve_lookup
    current = current()
              ^^^^^^^^^
  File "/usr/local/lib/python3.11/site-packages/django/forms/utils.py", line 88, in as_table
    return self.render(self.template_name_table)
           ^^^^^^^^^^^^^^^^^^^^^^^^^^^^^^^^^^^^^
  File "/usr/local/lib/python3.11/site-packages/django/forms/utils.py", line 67, in render
    context = context or self.get_context()
                         ^^^^^^^^^^^^^^^^^^
  File "/usr/local/lib/python3.11/site-packages/django/forms/forms.py", line 322, in get_context
    top_errors = self.non_field_errors().copy()
                 ^^^^^^^^^^^^^^^^^^^^^^^
  File "/usr/local/lib/python3.11/site-packages/django/forms/forms.py", line 358, in non_field_errors
    return self.errors.get(
           ^^^^^^^^^^^
  File "/usr/local/lib/python3.11/site-packages/django/forms/forms.py", line 196, in errors
    self.full_clean()
  File "/usr/local/lib/python3.11/site-packages/django/forms/forms.py", line 433, in full_clean
    self._clean_fields()
  File "/usr/local/lib/python3.11/site-packages/django/forms/forms.py", line 440, in _clean_fields
    value = bf.initial if field.disabled else bf.data
                                              ^^^^^^^
  File "/usr/local/lib/python3.11/site-packages/django/forms/boundfield.py", line 135, in data
    return self.form._widget_data_value(self.field.widget, self.html_name)
           ^^^^^^^^^^^^^^^^^^^^^^^^^^^^^^^^^^^^^^^^^^^^^^^^^^^^^^^^^^^^^^^
  File "/usr/local/lib/python3.11/site-packages/django/forms/forms.py", line 220, in _widget_data_value
    return widget.value_from_datadict(self.data, self.files, html_name)
           ^^^^^^^^^^^^^^^^^^^^^^^^^^^^^^^^^^^^^^^^^^^^^^^^^^^^^^^^^^^^
  File "/usr/local/lib/python3.11/site-packages/django/forms/widgets.py", line 297, in value_from_datadict
    return data.get(name)
           ^^^^^^^^
  File "/usr/local/lib/python3.11/site-packages/django/utils/functional.py", line 268, in inner
    return func(_wrapped, *args)
           ^^^^^^^^^^^^^^^^^^^^^
AttributeError: 'User' object has no attribute 'get'
"GET /create/ HTTP/1.1" 500 203452
Internal Server Error: /create/
Traceback (most recent call last):
  File "/usr/local/lib/python3.11/site-packages/django/core/handlers/exception.py", line 55, in inner
    response = get_response(request)
               ^^^^^^^^^^^^^^^^^^^^^
  File "/usr/local/lib/python3.11/site-packages/django/core/handlers/base.py", line 197, in _get_response
    response = wrapped_callback(request, *callback_args, **callback_kwargs)
               ^^^^^^^^^^^^^^^^^^^^^^^^^^^^^^^^^^^^^^^^^^^^^^^^^^^^^^^^^^^^
  File "/usr/local/lib/python3.11/site-packages/django/contrib/auth/decorators.py", line 23, in _wrapper_view
    return view_func(request, *args, **kwargs)
           ^^^^^^^^^^^^^^^^^^^^^^^^^^^^^^^^^^^
  File "/Users/taramanjimacbookpro/Documents/GitHub/OpenHackU2023_Ritskomachi/todo/views.py", line 148, in create_todo
    return render(request, 'todo/todo_form.html', {'form': form})
           ^^^^^^^^^^^^^^^^^^^^^^^^^^^^^^^^^^^^^^^^^^^^^^^^^^^^^^
  File "/usr/local/lib/python3.11/site-packages/django/shortcuts.py", line 24, in render
    content = loader.render_to_string(template_name, context, request, using=using)
              ^^^^^^^^^^^^^^^^^^^^^^^^^^^^^^^^^^^^^^^^^^^^^^^^^^^^^^^^^^^^^^^^^^^^^
  File "/usr/local/lib/python3.11/site-packages/django/template/loader.py", line 62, in render_to_string
    return template.render(context, request)
           ^^^^^^^^^^^^^^^^^^^^^^^^^^^^^^^^^
  File "/usr/local/lib/python3.11/site-packages/django/template/backends/django.py", line 61, in render
    return self.template.render(context)
           ^^^^^^^^^^^^^^^^^^^^^^^^^^^^^
  File "/usr/local/lib/python3.11/site-packages/django/template/base.py", line 175, in render
    return self._render(context)
           ^^^^^^^^^^^^^^^^^^^^^
  File "/usr/local/lib/python3.11/site-packages/django/template/base.py", line 167, in _render
    return self.nodelist.render(context)
           ^^^^^^^^^^^^^^^^^^^^^^^^^^^^^
  File "/usr/local/lib/python3.11/site-packages/django/template/base.py", line 1005, in render
    return SafeString("".join([node.render_annotated(context) for node in self]))
                              ^^^^^^^^^^^^^^^^^^^^^^^^^^^^^^^^^^^^^^^^^^^^^^^^^
  File "/usr/local/lib/python3.11/site-packages/django/template/base.py", line 1005, in <listcomp>
    return SafeString("".join([node.render_annotated(context) for node in self]))
                               ^^^^^^^^^^^^^^^^^^^^^^^^^^^^^^
  File "/usr/local/lib/python3.11/site-packages/django/template/base.py", line 966, in render_annotated
    return self.render(context)
           ^^^^^^^^^^^^^^^^^^^^
  File "/usr/local/lib/python3.11/site-packages/django/template/loader_tags.py", line 157, in render
    return compiled_parent._render(context)
           ^^^^^^^^^^^^^^^^^^^^^^^^^^^^^^^^
  File "/usr/local/lib/python3.11/site-packages/django/template/base.py", line 167, in _render
    return self.nodelist.render(context)
           ^^^^^^^^^^^^^^^^^^^^^^^^^^^^^
  File "/usr/local/lib/python3.11/site-packages/django/template/base.py", line 1005, in render
    return SafeString("".join([node.render_annotated(context) for node in self]))
                              ^^^^^^^^^^^^^^^^^^^^^^^^^^^^^^^^^^^^^^^^^^^^^^^^^
  File "/usr/local/lib/python3.11/site-packages/django/template/base.py", line 1005, in <listcomp>
    return SafeString("".join([node.render_annotated(context) for node in self]))
                               ^^^^^^^^^^^^^^^^^^^^^^^^^^^^^^
  File "/usr/local/lib/python3.11/site-packages/django/template/base.py", line 966, in render_annotated
    return self.render(context)
           ^^^^^^^^^^^^^^^^^^^^
  File "/usr/local/lib/python3.11/site-packages/django/template/loader_tags.py", line 63, in render
    result = block.nodelist.render(context)
             ^^^^^^^^^^^^^^^^^^^^^^^^^^^^^^
  File "/usr/local/lib/python3.11/site-packages/django/template/base.py", line 1005, in render
    return SafeString("".join([node.render_annotated(context) for node in self]))
                              ^^^^^^^^^^^^^^^^^^^^^^^^^^^^^^^^^^^^^^^^^^^^^^^^^
  File "/usr/local/lib/python3.11/site-packages/django/template/base.py", line 1005, in <listcomp>
    return SafeString("".join([node.render_annotated(context) for node in self]))
                               ^^^^^^^^^^^^^^^^^^^^^^^^^^^^^^
  File "/usr/local/lib/python3.11/site-packages/django/template/base.py", line 966, in render_annotated
    return self.render(context)
           ^^^^^^^^^^^^^^^^^^^^
  File "/usr/local/lib/python3.11/site-packages/django/template/base.py", line 1064, in render
    output = self.filter_expression.resolve(context)
             ^^^^^^^^^^^^^^^^^^^^^^^^^^^^^^^^^^^^^^^
  File "/usr/local/lib/python3.11/site-packages/django/template/base.py", line 715, in resolve
    obj = self.var.resolve(context)
          ^^^^^^^^^^^^^^^^^^^^^^^^^
  File "/usr/local/lib/python3.11/site-packages/django/template/base.py", line 847, in resolve
    value = self._resolve_lookup(context)
            ^^^^^^^^^^^^^^^^^^^^^^^^^^^^^
  File "/usr/local/lib/python3.11/site-packages/django/template/base.py", line 914, in _resolve_lookup
    current = current()
              ^^^^^^^^^
  File "/usr/local/lib/python3.11/site-packages/django/forms/utils.py", line 88, in as_table
    return self.render(self.template_name_table)
           ^^^^^^^^^^^^^^^^^^^^^^^^^^^^^^^^^^^^^
  File "/usr/local/lib/python3.11/site-packages/django/forms/utils.py", line 67, in render
    context = context or self.get_context()
                         ^^^^^^^^^^^^^^^^^^
  File "/usr/local/lib/python3.11/site-packages/django/forms/forms.py", line 322, in get_context
    top_errors = self.non_field_errors().copy()
                 ^^^^^^^^^^^^^^^^^^^^^^^
  File "/usr/local/lib/python3.11/site-packages/django/forms/forms.py", line 358, in non_field_errors
    return self.errors.get(
           ^^^^^^^^^^^
  File "/usr/local/lib/python3.11/site-packages/django/forms/forms.py", line 196, in errors
    self.full_clean()
  File "/usr/local/lib/python3.11/site-packages/django/forms/forms.py", line 433, in full_clean
    self._clean_fields()
  File "/usr/local/lib/python3.11/site-packages/django/forms/forms.py", line 440, in _clean_fields
    value = bf.initial if field.disabled else bf.data
                                              ^^^^^^^
  File "/usr/local/lib/python3.11/site-packages/django/forms/boundfield.py", line 135, in data
    return self.form._widget_data_value(self.field.widget, self.html_name)
           ^^^^^^^^^^^^^^^^^^^^^^^^^^^^^^^^^^^^^^^^^^^^^^^^^^^^^^^^^^^^^^^
  File "/usr/local/lib/python3.11/site-packages/django/forms/forms.py", line 220, in _widget_data_value
    return widget.value_from_datadict(self.data, self.files, html_name)
           ^^^^^^^^^^^^^^^^^^^^^^^^^^^^^^^^^^^^^^^^^^^^^^^^^^^^^^^^^^^^
  File "/usr/local/lib/python3.11/site-packages/django/forms/widgets.py", line 297, in value_from_datadict
    return data.get(name)
           ^^^^^^^^
  File "/usr/local/lib/python3.11/site-packages/django/utils/functional.py", line 268, in inner
    return func(_wrapped, *args)
           ^^^^^^^^^^^^^^^^^^^^^
AttributeError: 'User' object has no attribute 'get'
"GET /create/ HTTP/1.1" 500 203436
Internal Server Error: /create/
Traceback (most recent call last):
  File "/usr/local/lib/python3.11/site-packages/django/core/handlers/exception.py", line 55, in inner
    response = get_response(request)
               ^^^^^^^^^^^^^^^^^^^^^
  File "/usr/local/lib/python3.11/site-packages/django/core/handlers/base.py", line 197, in _get_response
    response = wrapped_callback(request, *callback_args, **callback_kwargs)
               ^^^^^^^^^^^^^^^^^^^^^^^^^^^^^^^^^^^^^^^^^^^^^^^^^^^^^^^^^^^^
  File "/usr/local/lib/python3.11/site-packages/django/contrib/auth/decorators.py", line 23, in _wrapper_view
    return view_func(request, *args, **kwargs)
           ^^^^^^^^^^^^^^^^^^^^^^^^^^^^^^^^^^^
  File "/Users/taramanjimacbookpro/Documents/GitHub/OpenHackU2023_Ritskomachi/todo/views.py", line 149, in create_todo
    return render(request, 'todo/todo_form.html', {'form': form})
           ^^^^^^^^^^^^^^^^^^^^^^^^^^^^^^^^^^^^^^^^^^^^^^^^^^^^^^
  File "/usr/local/lib/python3.11/site-packages/django/shortcuts.py", line 24, in render
    content = loader.render_to_string(template_name, context, request, using=using)
              ^^^^^^^^^^^^^^^^^^^^^^^^^^^^^^^^^^^^^^^^^^^^^^^^^^^^^^^^^^^^^^^^^^^^^
  File "/usr/local/lib/python3.11/site-packages/django/template/loader.py", line 62, in render_to_string
    return template.render(context, request)
           ^^^^^^^^^^^^^^^^^^^^^^^^^^^^^^^^^
  File "/usr/local/lib/python3.11/site-packages/django/template/backends/django.py", line 61, in render
    return self.template.render(context)
           ^^^^^^^^^^^^^^^^^^^^^^^^^^^^^
  File "/usr/local/lib/python3.11/site-packages/django/template/base.py", line 175, in render
    return self._render(context)
           ^^^^^^^^^^^^^^^^^^^^^
  File "/usr/local/lib/python3.11/site-packages/django/template/base.py", line 167, in _render
    return self.nodelist.render(context)
           ^^^^^^^^^^^^^^^^^^^^^^^^^^^^^
  File "/usr/local/lib/python3.11/site-packages/django/template/base.py", line 1005, in render
    return SafeString("".join([node.render_annotated(context) for node in self]))
                              ^^^^^^^^^^^^^^^^^^^^^^^^^^^^^^^^^^^^^^^^^^^^^^^^^
  File "/usr/local/lib/python3.11/site-packages/django/template/base.py", line 1005, in <listcomp>
    return SafeString("".join([node.render_annotated(context) for node in self]))
                               ^^^^^^^^^^^^^^^^^^^^^^^^^^^^^^
  File "/usr/local/lib/python3.11/site-packages/django/template/base.py", line 966, in render_annotated
    return self.render(context)
           ^^^^^^^^^^^^^^^^^^^^
  File "/usr/local/lib/python3.11/site-packages/django/template/loader_tags.py", line 157, in render
    return compiled_parent._render(context)
           ^^^^^^^^^^^^^^^^^^^^^^^^^^^^^^^^
  File "/usr/local/lib/python3.11/site-packages/django/template/base.py", line 167, in _render
    return self.nodelist.render(context)
           ^^^^^^^^^^^^^^^^^^^^^^^^^^^^^
  File "/usr/local/lib/python3.11/site-packages/django/template/base.py", line 1005, in render
    return SafeString("".join([node.render_annotated(context) for node in self]))
                              ^^^^^^^^^^^^^^^^^^^^^^^^^^^^^^^^^^^^^^^^^^^^^^^^^
  File "/usr/local/lib/python3.11/site-packages/django/template/base.py", line 1005, in <listcomp>
    return SafeString("".join([node.render_annotated(context) for node in self]))
                               ^^^^^^^^^^^^^^^^^^^^^^^^^^^^^^
  File "/usr/local/lib/python3.11/site-packages/django/template/base.py", line 966, in render_annotated
    return self.render(context)
           ^^^^^^^^^^^^^^^^^^^^
  File "/usr/local/lib/python3.11/site-packages/django/template/loader_tags.py", line 63, in render
    result = block.nodelist.render(context)
             ^^^^^^^^^^^^^^^^^^^^^^^^^^^^^^
  File "/usr/local/lib/python3.11/site-packages/django/template/base.py", line 1005, in render
    return SafeString("".join([node.render_annotated(context) for node in self]))
                              ^^^^^^^^^^^^^^^^^^^^^^^^^^^^^^^^^^^^^^^^^^^^^^^^^
  File "/usr/local/lib/python3.11/site-packages/django/template/base.py", line 1005, in <listcomp>
    return SafeString("".join([node.render_annotated(context) for node in self]))
                               ^^^^^^^^^^^^^^^^^^^^^^^^^^^^^^
  File "/usr/local/lib/python3.11/site-packages/django/template/base.py", line 966, in render_annotated
    return self.render(context)
           ^^^^^^^^^^^^^^^^^^^^
  File "/usr/local/lib/python3.11/site-packages/django/template/base.py", line 1064, in render
    output = self.filter_expression.resolve(context)
             ^^^^^^^^^^^^^^^^^^^^^^^^^^^^^^^^^^^^^^^
  File "/usr/local/lib/python3.11/site-packages/django/template/base.py", line 715, in resolve
    obj = self.var.resolve(context)
          ^^^^^^^^^^^^^^^^^^^^^^^^^
  File "/usr/local/lib/python3.11/site-packages/django/template/base.py", line 847, in resolve
    value = self._resolve_lookup(context)
            ^^^^^^^^^^^^^^^^^^^^^^^^^^^^^
  File "/usr/local/lib/python3.11/site-packages/django/template/base.py", line 914, in _resolve_lookup
    current = current()
              ^^^^^^^^^
  File "/usr/local/lib/python3.11/site-packages/django/forms/utils.py", line 88, in as_table
    return self.render(self.template_name_table)
           ^^^^^^^^^^^^^^^^^^^^^^^^^^^^^^^^^^^^^
  File "/usr/local/lib/python3.11/site-packages/django/forms/utils.py", line 67, in render
    context = context or self.get_context()
                         ^^^^^^^^^^^^^^^^^^
  File "/usr/local/lib/python3.11/site-packages/django/forms/forms.py", line 322, in get_context
    top_errors = self.non_field_errors().copy()
                 ^^^^^^^^^^^^^^^^^^^^^^^
  File "/usr/local/lib/python3.11/site-packages/django/forms/forms.py", line 358, in non_field_errors
    return self.errors.get(
           ^^^^^^^^^^^
  File "/usr/local/lib/python3.11/site-packages/django/forms/forms.py", line 196, in errors
    self.full_clean()
  File "/usr/local/lib/python3.11/site-packages/django/forms/forms.py", line 433, in full_clean
    self._clean_fields()
  File "/usr/local/lib/python3.11/site-packages/django/forms/forms.py", line 440, in _clean_fields
    value = bf.initial if field.disabled else bf.data
                                              ^^^^^^^
  File "/usr/local/lib/python3.11/site-packages/django/forms/boundfield.py", line 135, in data
    return self.form._widget_data_value(self.field.widget, self.html_name)
           ^^^^^^^^^^^^^^^^^^^^^^^^^^^^^^^^^^^^^^^^^^^^^^^^^^^^^^^^^^^^^^^
  File "/usr/local/lib/python3.11/site-packages/django/forms/forms.py", line 220, in _widget_data_value
    return widget.value_from_datadict(self.data, self.files, html_name)
           ^^^^^^^^^^^^^^^^^^^^^^^^^^^^^^^^^^^^^^^^^^^^^^^^^^^^^^^^^^^^
  File "/usr/local/lib/python3.11/site-packages/django/forms/widgets.py", line 297, in value_from_datadict
    return data.get(name)
           ^^^^^^^^
  File "/usr/local/lib/python3.11/site-packages/django/utils/functional.py", line 268, in inner
    return func(_wrapped, *args)
           ^^^^^^^^^^^^^^^^^^^^^
AttributeError: 'User' object has no attribute 'get'
"GET /create/ HTTP/1.1" 500 203436
Internal Server Error: /create/
Traceback (most recent call last):
  File "/usr/local/lib/python3.11/site-packages/django/core/handlers/exception.py", line 55, in inner
    response = get_response(request)
               ^^^^^^^^^^^^^^^^^^^^^
  File "/usr/local/lib/python3.11/site-packages/django/core/handlers/base.py", line 197, in _get_response
    response = wrapped_callback(request, *callback_args, **callback_kwargs)
               ^^^^^^^^^^^^^^^^^^^^^^^^^^^^^^^^^^^^^^^^^^^^^^^^^^^^^^^^^^^^
  File "/usr/local/lib/python3.11/site-packages/django/contrib/auth/decorators.py", line 23, in _wrapper_view
    return view_func(request, *args, **kwargs)
           ^^^^^^^^^^^^^^^^^^^^^^^^^^^^^^^^^^^
  File "/Users/taramanjimacbookpro/Documents/GitHub/OpenHackU2023_Ritskomachi/todo/views.py", line 150, in create_todo
    return render(request, 'todo/todo_form.html', {'form': form})
           ^^^^^^^^^^^^^^^^^^^^^^^^^^^^^^^^^^^^^^^^^^^^^^^^^^^^^^
  File "/usr/local/lib/python3.11/site-packages/django/shortcuts.py", line 24, in render
    content = loader.render_to_string(template_name, context, request, using=using)
              ^^^^^^^^^^^^^^^^^^^^^^^^^^^^^^^^^^^^^^^^^^^^^^^^^^^^^^^^^^^^^^^^^^^^^
  File "/usr/local/lib/python3.11/site-packages/django/template/loader.py", line 62, in render_to_string
    return template.render(context, request)
           ^^^^^^^^^^^^^^^^^^^^^^^^^^^^^^^^^
  File "/usr/local/lib/python3.11/site-packages/django/template/backends/django.py", line 61, in render
    return self.template.render(context)
           ^^^^^^^^^^^^^^^^^^^^^^^^^^^^^
  File "/usr/local/lib/python3.11/site-packages/django/template/base.py", line 175, in render
    return self._render(context)
           ^^^^^^^^^^^^^^^^^^^^^
  File "/usr/local/lib/python3.11/site-packages/django/template/base.py", line 167, in _render
    return self.nodelist.render(context)
           ^^^^^^^^^^^^^^^^^^^^^^^^^^^^^
  File "/usr/local/lib/python3.11/site-packages/django/template/base.py", line 1005, in render
    return SafeString("".join([node.render_annotated(context) for node in self]))
                              ^^^^^^^^^^^^^^^^^^^^^^^^^^^^^^^^^^^^^^^^^^^^^^^^^
  File "/usr/local/lib/python3.11/site-packages/django/template/base.py", line 1005, in <listcomp>
    return SafeString("".join([node.render_annotated(context) for node in self]))
                               ^^^^^^^^^^^^^^^^^^^^^^^^^^^^^^
  File "/usr/local/lib/python3.11/site-packages/django/template/base.py", line 966, in render_annotated
    return self.render(context)
           ^^^^^^^^^^^^^^^^^^^^
  File "/usr/local/lib/python3.11/site-packages/django/template/loader_tags.py", line 157, in render
    return compiled_parent._render(context)
           ^^^^^^^^^^^^^^^^^^^^^^^^^^^^^^^^
  File "/usr/local/lib/python3.11/site-packages/django/template/base.py", line 167, in _render
    return self.nodelist.render(context)
           ^^^^^^^^^^^^^^^^^^^^^^^^^^^^^
  File "/usr/local/lib/python3.11/site-packages/django/template/base.py", line 1005, in render
    return SafeString("".join([node.render_annotated(context) for node in self]))
                              ^^^^^^^^^^^^^^^^^^^^^^^^^^^^^^^^^^^^^^^^^^^^^^^^^
  File "/usr/local/lib/python3.11/site-packages/django/template/base.py", line 1005, in <listcomp>
    return SafeString("".join([node.render_annotated(context) for node in self]))
                               ^^^^^^^^^^^^^^^^^^^^^^^^^^^^^^
  File "/usr/local/lib/python3.11/site-packages/django/template/base.py", line 966, in render_annotated
    return self.render(context)
           ^^^^^^^^^^^^^^^^^^^^
  File "/usr/local/lib/python3.11/site-packages/django/template/loader_tags.py", line 63, in render
    result = block.nodelist.render(context)
             ^^^^^^^^^^^^^^^^^^^^^^^^^^^^^^
  File "/usr/local/lib/python3.11/site-packages/django/template/base.py", line 1005, in render
    return SafeString("".join([node.render_annotated(context) for node in self]))
                              ^^^^^^^^^^^^^^^^^^^^^^^^^^^^^^^^^^^^^^^^^^^^^^^^^
  File "/usr/local/lib/python3.11/site-packages/django/template/base.py", line 1005, in <listcomp>
    return SafeString("".join([node.render_annotated(context) for node in self]))
                               ^^^^^^^^^^^^^^^^^^^^^^^^^^^^^^
  File "/usr/local/lib/python3.11/site-packages/django/template/base.py", line 966, in render_annotated
    return self.render(context)
           ^^^^^^^^^^^^^^^^^^^^
  File "/usr/local/lib/python3.11/site-packages/django/template/base.py", line 1064, in render
    output = self.filter_expression.resolve(context)
             ^^^^^^^^^^^^^^^^^^^^^^^^^^^^^^^^^^^^^^^
  File "/usr/local/lib/python3.11/site-packages/django/template/base.py", line 715, in resolve
    obj = self.var.resolve(context)
          ^^^^^^^^^^^^^^^^^^^^^^^^^
  File "/usr/local/lib/python3.11/site-packages/django/template/base.py", line 847, in resolve
    value = self._resolve_lookup(context)
            ^^^^^^^^^^^^^^^^^^^^^^^^^^^^^
  File "/usr/local/lib/python3.11/site-packages/django/template/base.py", line 914, in _resolve_lookup
    current = current()
              ^^^^^^^^^
  File "/usr/local/lib/python3.11/site-packages/django/forms/utils.py", line 88, in as_table
    return self.render(self.template_name_table)
           ^^^^^^^^^^^^^^^^^^^^^^^^^^^^^^^^^^^^^
  File "/usr/local/lib/python3.11/site-packages/django/forms/utils.py", line 67, in render
    context = context or self.get_context()
                         ^^^^^^^^^^^^^^^^^^
  File "/usr/local/lib/python3.11/site-packages/django/forms/forms.py", line 322, in get_context
    top_errors = self.non_field_errors().copy()
                 ^^^^^^^^^^^^^^^^^^^^^^^
  File "/usr/local/lib/python3.11/site-packages/django/forms/forms.py", line 358, in non_field_errors
    return self.errors.get(
           ^^^^^^^^^^^
  File "/usr/local/lib/python3.11/site-packages/django/forms/forms.py", line 196, in errors
    self.full_clean()
  File "/usr/local/lib/python3.11/site-packages/django/forms/forms.py", line 433, in full_clean
    self._clean_fields()
  File "/usr/local/lib/python3.11/site-packages/django/forms/forms.py", line 440, in _clean_fields
    value = bf.initial if field.disabled else bf.data
                                              ^^^^^^^
  File "/usr/local/lib/python3.11/site-packages/django/forms/boundfield.py", line 135, in data
    return self.form._widget_data_value(self.field.widget, self.html_name)
           ^^^^^^^^^^^^^^^^^^^^^^^^^^^^^^^^^^^^^^^^^^^^^^^^^^^^^^^^^^^^^^^
  File "/usr/local/lib/python3.11/site-packages/django/forms/forms.py", line 220, in _widget_data_value
    return widget.value_from_datadict(self.data, self.files, html_name)
           ^^^^^^^^^^^^^^^^^^^^^^^^^^^^^^^^^^^^^^^^^^^^^^^^^^^^^^^^^^^^
  File "/usr/local/lib/python3.11/site-packages/django/forms/widgets.py", line 297, in value_from_datadict
    return data.get(name)
           ^^^^^^^^
  File "/usr/local/lib/python3.11/site-packages/django/utils/functional.py", line 268, in inner
    return func(_wrapped, *args)
           ^^^^^^^^^^^^^^^^^^^^^
AttributeError: 'User' object has no attribute 'get'
"GET /create/ HTTP/1.1" 500 203397
Internal Server Error: /create/
Traceback (most recent call last):
  File "/usr/local/lib/python3.11/site-packages/django/db/models/fields/related_descriptors.py", line 218, in __get__
    rel_obj = self.field.get_cached_value(instance)
              ^^^^^^^^^^^^^^^^^^^^^^^^^^^^^^^^^^^^^
  File "/usr/local/lib/python3.11/site-packages/django/db/models/fields/mixins.py", line 15, in get_cached_value
    return instance._state.fields_cache[cache_name]
           ~~~~~~~~~~~~~~~~~~~~~~~~~~~~^^^^^^^^^^^^
KeyError: 'tag'

During handling of the above exception, another exception occurred:

Traceback (most recent call last):
  File "/usr/local/lib/python3.11/site-packages/django/db/models/fields/__init__.py", line 2053, in get_prep_value
    return int(value)
           ^^^^^^^^^^
ValueError: invalid literal for int() with base 10: ''

The above exception was the direct cause of the following exception:

Traceback (most recent call last):
  File "/usr/local/lib/python3.11/site-packages/django/core/handlers/exception.py", line 55, in inner
    response = get_response(request)
               ^^^^^^^^^^^^^^^^^^^^^
  File "/usr/local/lib/python3.11/site-packages/django/core/handlers/base.py", line 197, in _get_response
    response = wrapped_callback(request, *callback_args, **callback_kwargs)
               ^^^^^^^^^^^^^^^^^^^^^^^^^^^^^^^^^^^^^^^^^^^^^^^^^^^^^^^^^^^^
  File "/usr/local/lib/python3.11/site-packages/django/contrib/auth/decorators.py", line 23, in _wrapper_view
    return view_func(request, *args, **kwargs)
           ^^^^^^^^^^^^^^^^^^^^^^^^^^^^^^^^^^^
  File "/Users/taramanjimacbookpro/Documents/GitHub/OpenHackU2023_Ritskomachi/todo/views.py", line 144, in create_todo
    tag=todo.tag if todo.tag else None
                    ^^^^^^^^
  File "/usr/local/lib/python3.11/site-packages/django/db/models/fields/related_descriptors.py", line 236, in __get__
    rel_obj = self.get_object(instance)
              ^^^^^^^^^^^^^^^^^^^^^^^^^
  File "/usr/local/lib/python3.11/site-packages/django/db/models/fields/related_descriptors.py", line 199, in get_object
    return qs.get(self.field.get_reverse_related_filter(instance))
           ^^^^^^^^^^^^^^^^^^^^^^^^^^^^^^^^^^^^^^^^^^^^^^^^^^^^^^^
  File "/usr/local/lib/python3.11/site-packages/django/db/models/query.py", line 623, in get
    clone = self._chain() if self.query.combinator else self.filter(*args, **kwargs)
                                                        ^^^^^^^^^^^^^^^^^^^^^^^^^^^^
  File "/usr/local/lib/python3.11/site-packages/django/db/models/query.py", line 1436, in filter
    return self._filter_or_exclude(False, args, kwargs)
           ^^^^^^^^^^^^^^^^^^^^^^^^^^^^^^^^^^^^^^^^^^^^
  File "/usr/local/lib/python3.11/site-packages/django/db/models/query.py", line 1454, in _filter_or_exclude
    clone._filter_or_exclude_inplace(negate, args, kwargs)
  File "/usr/local/lib/python3.11/site-packages/django/db/models/query.py", line 1461, in _filter_or_exclude_inplace
    self._query.add_q(Q(*args, **kwargs))
  File "/usr/local/lib/python3.11/site-packages/django/db/models/sql/query.py", line 1545, in add_q
    clause, _ = self._add_q(q_object, self.used_aliases)
                ^^^^^^^^^^^^^^^^^^^^^^^^^^^^^^^^^^^^^^^^
  File "/usr/local/lib/python3.11/site-packages/django/db/models/sql/query.py", line 1576, in _add_q
    child_clause, needed_inner = self.build_filter(
                                 ^^^^^^^^^^^^^^^^^^
  File "/usr/local/lib/python3.11/site-packages/django/db/models/sql/query.py", line 1404, in build_filter
    return self._add_q(
           ^^^^^^^^^^^^
  File "/usr/local/lib/python3.11/site-packages/django/db/models/sql/query.py", line 1576, in _add_q
    child_clause, needed_inner = self.build_filter(
                                 ^^^^^^^^^^^^^^^^^^
  File "/usr/local/lib/python3.11/site-packages/django/db/models/sql/query.py", line 1491, in build_filter
    condition = self.build_lookup(lookups, col, value)
                ^^^^^^^^^^^^^^^^^^^^^^^^^^^^^^^^^^^^^^
  File "/usr/local/lib/python3.11/site-packages/django/db/models/sql/query.py", line 1318, in build_lookup
    lookup = lookup_class(lhs, rhs)
             ^^^^^^^^^^^^^^^^^^^^^^
  File "/usr/local/lib/python3.11/site-packages/django/db/models/lookups.py", line 27, in __init__
    self.rhs = self.get_prep_lookup()
               ^^^^^^^^^^^^^^^^^^^^^^
  File "/usr/local/lib/python3.11/site-packages/django/db/models/lookups.py", line 341, in get_prep_lookup
    return super().get_prep_lookup()
           ^^^^^^^^^^^^^^^^^^^^^^^^^
  File "/usr/local/lib/python3.11/site-packages/django/db/models/lookups.py", line 85, in get_prep_lookup
    return self.lhs.output_field.get_prep_value(self.rhs)
           ^^^^^^^^^^^^^^^^^^^^^^^^^^^^^^^^^^^^^^^^^^^^^^
  File "/usr/local/lib/python3.11/site-packages/django/db/models/fields/__init__.py", line 2055, in get_prep_value
    raise e.__class__(
ValueError: Field 'id' expected a number but got ''.
"POST /create/ HTTP/1.1" 500 155179
Internal Server Error: /create/
Traceback (most recent call last):
  File "/usr/local/lib/python3.11/site-packages/django/db/models/fields/related_descriptors.py", line 218, in __get__
    rel_obj = self.field.get_cached_value(instance)
              ^^^^^^^^^^^^^^^^^^^^^^^^^^^^^^^^^^^^^
  File "/usr/local/lib/python3.11/site-packages/django/db/models/fields/mixins.py", line 15, in get_cached_value
    return instance._state.fields_cache[cache_name]
           ~~~~~~~~~~~~~~~~~~~~~~~~~~~~^^^^^^^^^^^^
KeyError: 'tag'

During handling of the above exception, another exception occurred:

Traceback (most recent call last):
  File "/usr/local/lib/python3.11/site-packages/django/db/models/fields/__init__.py", line 2053, in get_prep_value
    return int(value)
           ^^^^^^^^^^
ValueError: invalid literal for int() with base 10: ''

The above exception was the direct cause of the following exception:

Traceback (most recent call last):
  File "/usr/local/lib/python3.11/site-packages/django/core/handlers/exception.py", line 55, in inner
    response = get_response(request)
               ^^^^^^^^^^^^^^^^^^^^^
  File "/usr/local/lib/python3.11/site-packages/django/core/handlers/base.py", line 197, in _get_response
    response = wrapped_callback(request, *callback_args, **callback_kwargs)
               ^^^^^^^^^^^^^^^^^^^^^^^^^^^^^^^^^^^^^^^^^^^^^^^^^^^^^^^^^^^^
  File "/usr/local/lib/python3.11/site-packages/django/contrib/auth/decorators.py", line 23, in _wrapper_view
    return view_func(request, *args, **kwargs)
           ^^^^^^^^^^^^^^^^^^^^^^^^^^^^^^^^^^^
  File "/Users/taramanjimacbookpro/Documents/GitHub/OpenHackU2023_Ritskomachi/todo/views.py", line 144, in create_todo
    tag=todo.tag if todo.tag else None
                    ^^^^^^^^
  File "/usr/local/lib/python3.11/site-packages/django/db/models/fields/related_descriptors.py", line 236, in __get__
    rel_obj = self.get_object(instance)
              ^^^^^^^^^^^^^^^^^^^^^^^^^
  File "/usr/local/lib/python3.11/site-packages/django/db/models/fields/related_descriptors.py", line 199, in get_object
    return qs.get(self.field.get_reverse_related_filter(instance))
           ^^^^^^^^^^^^^^^^^^^^^^^^^^^^^^^^^^^^^^^^^^^^^^^^^^^^^^^
  File "/usr/local/lib/python3.11/site-packages/django/db/models/query.py", line 623, in get
    clone = self._chain() if self.query.combinator else self.filter(*args, **kwargs)
                                                        ^^^^^^^^^^^^^^^^^^^^^^^^^^^^
  File "/usr/local/lib/python3.11/site-packages/django/db/models/query.py", line 1436, in filter
    return self._filter_or_exclude(False, args, kwargs)
           ^^^^^^^^^^^^^^^^^^^^^^^^^^^^^^^^^^^^^^^^^^^^
  File "/usr/local/lib/python3.11/site-packages/django/db/models/query.py", line 1454, in _filter_or_exclude
    clone._filter_or_exclude_inplace(negate, args, kwargs)
  File "/usr/local/lib/python3.11/site-packages/django/db/models/query.py", line 1461, in _filter_or_exclude_inplace
    self._query.add_q(Q(*args, **kwargs))
  File "/usr/local/lib/python3.11/site-packages/django/db/models/sql/query.py", line 1545, in add_q
    clause, _ = self._add_q(q_object, self.used_aliases)
                ^^^^^^^^^^^^^^^^^^^^^^^^^^^^^^^^^^^^^^^^
  File "/usr/local/lib/python3.11/site-packages/django/db/models/sql/query.py", line 1576, in _add_q
    child_clause, needed_inner = self.build_filter(
                                 ^^^^^^^^^^^^^^^^^^
  File "/usr/local/lib/python3.11/site-packages/django/db/models/sql/query.py", line 1404, in build_filter
    return self._add_q(
           ^^^^^^^^^^^^
  File "/usr/local/lib/python3.11/site-packages/django/db/models/sql/query.py", line 1576, in _add_q
    child_clause, needed_inner = self.build_filter(
                                 ^^^^^^^^^^^^^^^^^^
  File "/usr/local/lib/python3.11/site-packages/django/db/models/sql/query.py", line 1491, in build_filter
    condition = self.build_lookup(lookups, col, value)
                ^^^^^^^^^^^^^^^^^^^^^^^^^^^^^^^^^^^^^^
  File "/usr/local/lib/python3.11/site-packages/django/db/models/sql/query.py", line 1318, in build_lookup
    lookup = lookup_class(lhs, rhs)
             ^^^^^^^^^^^^^^^^^^^^^^
  File "/usr/local/lib/python3.11/site-packages/django/db/models/lookups.py", line 27, in __init__
    self.rhs = self.get_prep_lookup()
               ^^^^^^^^^^^^^^^^^^^^^^
  File "/usr/local/lib/python3.11/site-packages/django/db/models/lookups.py", line 341, in get_prep_lookup
    return super().get_prep_lookup()
           ^^^^^^^^^^^^^^^^^^^^^^^^^
  File "/usr/local/lib/python3.11/site-packages/django/db/models/lookups.py", line 85, in get_prep_lookup
    return self.lhs.output_field.get_prep_value(self.rhs)
           ^^^^^^^^^^^^^^^^^^^^^^^^^^^^^^^^^^^^^^^^^^^^^^
  File "/usr/local/lib/python3.11/site-packages/django/db/models/fields/__init__.py", line 2055, in get_prep_value
    raise e.__class__(
ValueError: Field 'id' expected a number but got ''.
"POST /create/ HTTP/1.1" 500 155179
Internal Server Error: /create/
Traceback (most recent call last):
  File "/usr/local/lib/python3.11/site-packages/django/db/backends/utils.py", line 89, in _execute
    return self.cursor.execute(sql, params)
           ^^^^^^^^^^^^^^^^^^^^^^^^^^^^^^^^
  File "/usr/local/lib/python3.11/site-packages/django/db/backends/mysql/base.py", line 75, in execute
    return self.cursor.execute(query, args)
           ^^^^^^^^^^^^^^^^^^^^^^^^^^^^^^^^
  File "/usr/local/lib/python3.11/site-packages/pymysql/cursors.py", line 153, in execute
    result = self._query(query)
             ^^^^^^^^^^^^^^^^^^
  File "/usr/local/lib/python3.11/site-packages/pymysql/cursors.py", line 322, in _query
    conn.query(q)
  File "/usr/local/lib/python3.11/site-packages/pymysql/connections.py", line 558, in query
    self._affected_rows = self._read_query_result(unbuffered=unbuffered)
                          ^^^^^^^^^^^^^^^^^^^^^^^^^^^^^^^^^^^^^^^^^^^^^^
  File "/usr/local/lib/python3.11/site-packages/pymysql/connections.py", line 822, in _read_query_result
    result.read()
  File "/usr/local/lib/python3.11/site-packages/pymysql/connections.py", line 1200, in read
    first_packet = self.connection._read_packet()
                   ^^^^^^^^^^^^^^^^^^^^^^^^^^^^^^
  File "/usr/local/lib/python3.11/site-packages/pymysql/connections.py", line 772, in _read_packet
    packet.raise_for_error()
  File "/usr/local/lib/python3.11/site-packages/pymysql/protocol.py", line 221, in raise_for_error
    err.raise_mysql_exception(self._data)
  File "/usr/local/lib/python3.11/site-packages/pymysql/err.py", line 143, in raise_mysql_exception
    raise errorclass(errno, errval)
pymysql.err.IntegrityError: (1048, "Column 'deadline' cannot be null")

The above exception was the direct cause of the following exception:

Traceback (most recent call last):
  File "/usr/local/lib/python3.11/site-packages/django/core/handlers/exception.py", line 55, in inner
    response = get_response(request)
               ^^^^^^^^^^^^^^^^^^^^^
  File "/usr/local/lib/python3.11/site-packages/django/core/handlers/base.py", line 197, in _get_response
    response = wrapped_callback(request, *callback_args, **callback_kwargs)
               ^^^^^^^^^^^^^^^^^^^^^^^^^^^^^^^^^^^^^^^^^^^^^^^^^^^^^^^^^^^^
  File "/usr/local/lib/python3.11/site-packages/django/contrib/auth/decorators.py", line 23, in _wrapper_view
    return view_func(request, *args, **kwargs)
           ^^^^^^^^^^^^^^^^^^^^^^^^^^^^^^^^^^^
  File "/Users/taramanjimacbookpro/Documents/GitHub/OpenHackU2023_Ritskomachi/todo/views.py", line 137, in create_todo
    TodoDay.objects.create(
  File "/usr/local/lib/python3.11/site-packages/django/db/models/manager.py", line 87, in manager_method
    return getattr(self.get_queryset(), name)(*args, **kwargs)
           ^^^^^^^^^^^^^^^^^^^^^^^^^^^^^^^^^^^^^^^^^^^^^^^^^^^
  File "/usr/local/lib/python3.11/site-packages/django/db/models/query.py", line 658, in create
    obj.save(force_insert=True, using=self.db)
  File "/Users/taramanjimacbookpro/Documents/GitHub/OpenHackU2023_Ritskomachi/todo/models.py", line 50, in save
    super(TodoDay, self).save(*args, **kwargs)
  File "/usr/local/lib/python3.11/site-packages/django/db/models/base.py", line 814, in save
    self.save_base(
  File "/usr/local/lib/python3.11/site-packages/django/db/models/base.py", line 877, in save_base
    updated = self._save_table(
              ^^^^^^^^^^^^^^^^^
  File "/usr/local/lib/python3.11/site-packages/django/db/models/base.py", line 1020, in _save_table
    results = self._do_insert(
              ^^^^^^^^^^^^^^^^
  File "/usr/local/lib/python3.11/site-packages/django/db/models/base.py", line 1061, in _do_insert
    return manager._insert(
           ^^^^^^^^^^^^^^^^
  File "/usr/local/lib/python3.11/site-packages/django/db/models/manager.py", line 87, in manager_method
    return getattr(self.get_queryset(), name)(*args, **kwargs)
           ^^^^^^^^^^^^^^^^^^^^^^^^^^^^^^^^^^^^^^^^^^^^^^^^^^^
  File "/usr/local/lib/python3.11/site-packages/django/db/models/query.py", line 1805, in _insert
    return query.get_compiler(using=using).execute_sql(returning_fields)
           ^^^^^^^^^^^^^^^^^^^^^^^^^^^^^^^^^^^^^^^^^^^^^^^^^^^^^^^^^^^^^
  File "/usr/local/lib/python3.11/site-packages/django/db/models/sql/compiler.py", line 1822, in execute_sql
    cursor.execute(sql, params)
  File "/usr/local/lib/python3.11/site-packages/django/db/backends/utils.py", line 102, in execute
    return super().execute(sql, params)
           ^^^^^^^^^^^^^^^^^^^^^^^^^^^^
  File "/usr/local/lib/python3.11/site-packages/django/db/backends/utils.py", line 67, in execute
    return self._execute_with_wrappers(
           ^^^^^^^^^^^^^^^^^^^^^^^^^^^^
  File "/usr/local/lib/python3.11/site-packages/django/db/backends/utils.py", line 80, in _execute_with_wrappers
    return executor(sql, params, many, context)
           ^^^^^^^^^^^^^^^^^^^^^^^^^^^^^^^^^^^^
  File "/usr/local/lib/python3.11/site-packages/django/db/backends/utils.py", line 84, in _execute
    with self.db.wrap_database_errors:
  File "/usr/local/lib/python3.11/site-packages/django/db/utils.py", line 91, in __exit__
    raise dj_exc_value.with_traceback(traceback) from exc_value
  File "/usr/local/lib/python3.11/site-packages/django/db/backends/utils.py", line 89, in _execute
    return self.cursor.execute(sql, params)
           ^^^^^^^^^^^^^^^^^^^^^^^^^^^^^^^^
  File "/usr/local/lib/python3.11/site-packages/django/db/backends/mysql/base.py", line 75, in execute
    return self.cursor.execute(query, args)
           ^^^^^^^^^^^^^^^^^^^^^^^^^^^^^^^^
  File "/usr/local/lib/python3.11/site-packages/pymysql/cursors.py", line 153, in execute
    result = self._query(query)
             ^^^^^^^^^^^^^^^^^^
  File "/usr/local/lib/python3.11/site-packages/pymysql/cursors.py", line 322, in _query
    conn.query(q)
  File "/usr/local/lib/python3.11/site-packages/pymysql/connections.py", line 558, in query
    self._affected_rows = self._read_query_result(unbuffered=unbuffered)
                          ^^^^^^^^^^^^^^^^^^^^^^^^^^^^^^^^^^^^^^^^^^^^^^
  File "/usr/local/lib/python3.11/site-packages/pymysql/connections.py", line 822, in _read_query_result
    result.read()
  File "/usr/local/lib/python3.11/site-packages/pymysql/connections.py", line 1200, in read
    first_packet = self.connection._read_packet()
                   ^^^^^^^^^^^^^^^^^^^^^^^^^^^^^^
  File "/usr/local/lib/python3.11/site-packages/pymysql/connections.py", line 772, in _read_packet
    packet.raise_for_error()
  File "/usr/local/lib/python3.11/site-packages/pymysql/protocol.py", line 221, in raise_for_error
    err.raise_mysql_exception(self._data)
  File "/usr/local/lib/python3.11/site-packages/pymysql/err.py", line 143, in raise_mysql_exception
    raise errorclass(errno, errval)
django.db.utils.IntegrityError: (1048, "Column 'deadline' cannot be null")
"POST /create/ HTTP/1.1" 500 218698
Internal Server Error: /create_category/
Traceback (most recent call last):
  File "/usr/local/lib/python3.11/site-packages/django/core/handlers/exception.py", line 55, in inner
    response = get_response(request)
               ^^^^^^^^^^^^^^^^^^^^^
  File "/usr/local/lib/python3.11/site-packages/django/core/handlers/base.py", line 197, in _get_response
    response = wrapped_callback(request, *callback_args, **callback_kwargs)
               ^^^^^^^^^^^^^^^^^^^^^^^^^^^^^^^^^^^^^^^^^^^^^^^^^^^^^^^^^^^^
  File "/usr/local/lib/python3.11/site-packages/django/contrib/auth/decorators.py", line 23, in _wrapper_view
    return view_func(request, *args, **kwargs)
           ^^^^^^^^^^^^^^^^^^^^^^^^^^^^^^^^^^^
  File "/Users/taramanjimacbookpro/Documents/GitHub/OpenHackU2023_Ritskomachi/todo/views.py", line 210, in create_tag
    TodoDay.objects.create(
  File "/usr/local/lib/python3.11/site-packages/django/db/models/manager.py", line 87, in manager_method
    return getattr(self.get_queryset(), name)(*args, **kwargs)
           ^^^^^^^^^^^^^^^^^^^^^^^^^^^^^^^^^^^^^^^^^^^^^^^^^^^
  File "/usr/local/lib/python3.11/site-packages/django/db/models/query.py", line 656, in create
    obj = self.model(**kwargs)
          ^^^^^^^^^^^^^^^^^^^^
  File "/usr/local/lib/python3.11/site-packages/django/db/models/base.py", line 567, in __init__
    raise TypeError(
TypeError: TodoDay() got unexpected keyword arguments: 'name'
"POST /create_category/ HTTP/1.1" 500 80882
Internal Server Error: /create_category/
Traceback (most recent call last):
  File "/usr/local/lib/python3.11/site-packages/django/core/handlers/exception.py", line 55, in inner
    response = get_response(request)
               ^^^^^^^^^^^^^^^^^^^^^
  File "/usr/local/lib/python3.11/site-packages/django/core/handlers/base.py", line 197, in _get_response
    response = wrapped_callback(request, *callback_args, **callback_kwargs)
               ^^^^^^^^^^^^^^^^^^^^^^^^^^^^^^^^^^^^^^^^^^^^^^^^^^^^^^^^^^^^
  File "/usr/local/lib/python3.11/site-packages/django/contrib/auth/decorators.py", line 23, in _wrapper_view
    return view_func(request, *args, **kwargs)
           ^^^^^^^^^^^^^^^^^^^^^^^^^^^^^^^^^^^
  File "/Users/taramanjimacbookpro/Documents/GitHub/OpenHackU2023_Ritskomachi/todo/views.py", line 210, in create_tag
    Tag.objects.create(
  File "/usr/local/lib/python3.11/site-packages/django/db/models/manager.py", line 87, in manager_method
    return getattr(self.get_queryset(), name)(*args, **kwargs)
           ^^^^^^^^^^^^^^^^^^^^^^^^^^^^^^^^^^^^^^^^^^^^^^^^^^^
  File "/usr/local/lib/python3.11/site-packages/django/db/models/query.py", line 656, in create
    obj = self.model(**kwargs)
          ^^^^^^^^^^^^^^^^^^^^
  File "/usr/local/lib/python3.11/site-packages/django/db/models/base.py", line 567, in __init__
    raise TypeError(
TypeError: Tag() got unexpected keyword arguments: 'tag'
"POST /create_category/ HTTP/1.1" 500 80889
Internal Server Error: /todo_category/
Traceback (most recent call last):
  File "/usr/local/lib/python3.11/site-packages/django/core/handlers/exception.py", line 55, in inner
    response = get_response(request)
               ^^^^^^^^^^^^^^^^^^^^^
  File "/usr/local/lib/python3.11/site-packages/django/core/handlers/base.py", line 220, in _get_response
    response = response.render()
               ^^^^^^^^^^^^^^^^^
  File "/usr/local/lib/python3.11/site-packages/django/template/response.py", line 114, in render
    self.content = self.rendered_content
                   ^^^^^^^^^^^^^^^^^^^^^
  File "/usr/local/lib/python3.11/site-packages/django/template/response.py", line 92, in rendered_content
    return template.render(context, self._request)
           ^^^^^^^^^^^^^^^^^^^^^^^^^^^^^^^^^^^^^^^
  File "/usr/local/lib/python3.11/site-packages/django/template/backends/django.py", line 61, in render
    return self.template.render(context)
           ^^^^^^^^^^^^^^^^^^^^^^^^^^^^^
  File "/usr/local/lib/python3.11/site-packages/django/template/base.py", line 175, in render
    return self._render(context)
           ^^^^^^^^^^^^^^^^^^^^^
  File "/usr/local/lib/python3.11/site-packages/django/template/base.py", line 167, in _render
    return self.nodelist.render(context)
           ^^^^^^^^^^^^^^^^^^^^^^^^^^^^^
  File "/usr/local/lib/python3.11/site-packages/django/template/base.py", line 1005, in render
    return SafeString("".join([node.render_annotated(context) for node in self]))
                              ^^^^^^^^^^^^^^^^^^^^^^^^^^^^^^^^^^^^^^^^^^^^^^^^^
  File "/usr/local/lib/python3.11/site-packages/django/template/base.py", line 1005, in <listcomp>
    return SafeString("".join([node.render_annotated(context) for node in self]))
                               ^^^^^^^^^^^^^^^^^^^^^^^^^^^^^^
  File "/usr/local/lib/python3.11/site-packages/django/template/base.py", line 966, in render_annotated
    return self.render(context)
           ^^^^^^^^^^^^^^^^^^^^
  File "/usr/local/lib/python3.11/site-packages/django/template/defaulttags.py", line 238, in render
    nodelist.append(node.render_annotated(context))
                    ^^^^^^^^^^^^^^^^^^^^^^^^^^^^^^
  File "/usr/local/lib/python3.11/site-packages/django/template/base.py", line 966, in render_annotated
    return self.render(context)
           ^^^^^^^^^^^^^^^^^^^^
  File "/usr/local/lib/python3.11/site-packages/django/template/defaulttags.py", line 471, in render
    url = reverse(view_name, args=args, kwargs=kwargs, current_app=current_app)
          ^^^^^^^^^^^^^^^^^^^^^^^^^^^^^^^^^^^^^^^^^^^^^^^^^^^^^^^^^^^^^^^^^^^^^
  File "/usr/local/lib/python3.11/site-packages/django/urls/base.py", line 88, in reverse
    return resolver._reverse_with_prefix(view, prefix, *args, **kwargs)
           ^^^^^^^^^^^^^^^^^^^^^^^^^^^^^^^^^^^^^^^^^^^^^^^^^^^^^^^^^^^^
  File "/usr/local/lib/python3.11/site-packages/django/urls/resolvers.py", line 828, in _reverse_with_prefix
    raise NoReverseMatch(msg)
django.urls.exceptions.NoReverseMatch: Reverse for 'edit_tag' not found. 'edit_tag' is not a valid view function or pattern name.
"GET /todo_category/ HTTP/1.1" 500 125318
Internal Server Error: /create_category/
Traceback (most recent call last):
  File "/usr/local/lib/python3.11/site-packages/django/core/handlers/exception.py", line 55, in inner
    response = get_response(request)
               ^^^^^^^^^^^^^^^^^^^^^
  File "/usr/local/lib/python3.11/site-packages/django/core/handlers/base.py", line 197, in _get_response
    response = wrapped_callback(request, *callback_args, **callback_kwargs)
               ^^^^^^^^^^^^^^^^^^^^^^^^^^^^^^^^^^^^^^^^^^^^^^^^^^^^^^^^^^^^
  File "/Users/taramanjimacbookpro/Documents/GitHub/OpenHackU2023_Ritskomachi/todo/views.py", line 214, in create_tag
    return render(request, 'path_to_create_template.html', {'form': form})
           ^^^^^^^^^^^^^^^^^^^^^^^^^^^^^^^^^^^^^^^^^^^^^^^^^^^^^^^^^^^^^^^
  File "/usr/local/lib/python3.11/site-packages/django/shortcuts.py", line 24, in render
    content = loader.render_to_string(template_name, context, request, using=using)
              ^^^^^^^^^^^^^^^^^^^^^^^^^^^^^^^^^^^^^^^^^^^^^^^^^^^^^^^^^^^^^^^^^^^^^
  File "/usr/local/lib/python3.11/site-packages/django/template/loader.py", line 61, in render_to_string
    template = get_template(template_name, using=using)
               ^^^^^^^^^^^^^^^^^^^^^^^^^^^^^^^^^^^^^^^^
  File "/usr/local/lib/python3.11/site-packages/django/template/loader.py", line 19, in get_template
    raise TemplateDoesNotExist(template_name, chain=chain)
django.template.exceptions.TemplateDoesNotExist: path_to_create_template.html
"GET /create_category/ HTTP/1.1" 500 76142
Internal Server Error: /create_category/
Traceback (most recent call last):
  File "/usr/local/lib/python3.11/site-packages/django/db/backends/utils.py", line 89, in _execute
    return self.cursor.execute(sql, params)
           ^^^^^^^^^^^^^^^^^^^^^^^^^^^^^^^^
  File "/usr/local/lib/python3.11/site-packages/django/db/backends/mysql/base.py", line 75, in execute
    return self.cursor.execute(query, args)
           ^^^^^^^^^^^^^^^^^^^^^^^^^^^^^^^^
  File "/usr/local/lib/python3.11/site-packages/pymysql/cursors.py", line 153, in execute
    result = self._query(query)
             ^^^^^^^^^^^^^^^^^^
  File "/usr/local/lib/python3.11/site-packages/pymysql/cursors.py", line 322, in _query
    conn.query(q)
  File "/usr/local/lib/python3.11/site-packages/pymysql/connections.py", line 558, in query
    self._affected_rows = self._read_query_result(unbuffered=unbuffered)
                          ^^^^^^^^^^^^^^^^^^^^^^^^^^^^^^^^^^^^^^^^^^^^^^
  File "/usr/local/lib/python3.11/site-packages/pymysql/connections.py", line 822, in _read_query_result
    result.read()
  File "/usr/local/lib/python3.11/site-packages/pymysql/connections.py", line 1200, in read
    first_packet = self.connection._read_packet()
                   ^^^^^^^^^^^^^^^^^^^^^^^^^^^^^^
  File "/usr/local/lib/python3.11/site-packages/pymysql/connections.py", line 772, in _read_packet
    packet.raise_for_error()
  File "/usr/local/lib/python3.11/site-packages/pymysql/protocol.py", line 221, in raise_for_error
    err.raise_mysql_exception(self._data)
  File "/usr/local/lib/python3.11/site-packages/pymysql/err.py", line 143, in raise_mysql_exception
    raise errorclass(errno, errval)
pymysql.err.IntegrityError: (1048, "Column 'user_id' cannot be null")

The above exception was the direct cause of the following exception:

Traceback (most recent call last):
  File "/usr/local/lib/python3.11/site-packages/django/core/handlers/exception.py", line 55, in inner
    response = get_response(request)
               ^^^^^^^^^^^^^^^^^^^^^
  File "/usr/local/lib/python3.11/site-packages/django/core/handlers/base.py", line 197, in _get_response
    response = wrapped_callback(request, *callback_args, **callback_kwargs)
               ^^^^^^^^^^^^^^^^^^^^^^^^^^^^^^^^^^^^^^^^^^^^^^^^^^^^^^^^^^^^
  File "/Users/taramanjimacbookpro/Documents/GitHub/OpenHackU2023_Ritskomachi/todo/views.py", line 208, in create_tag
    form.save()
  File "/usr/local/lib/python3.11/site-packages/django/forms/models.py", line 542, in save
    self.instance.save()
  File "/usr/local/lib/python3.11/site-packages/django/db/models/base.py", line 814, in save
    self.save_base(
  File "/usr/local/lib/python3.11/site-packages/django/db/models/base.py", line 877, in save_base
    updated = self._save_table(
              ^^^^^^^^^^^^^^^^^
  File "/usr/local/lib/python3.11/site-packages/django/db/models/base.py", line 1020, in _save_table
    results = self._do_insert(
              ^^^^^^^^^^^^^^^^
  File "/usr/local/lib/python3.11/site-packages/django/db/models/base.py", line 1061, in _do_insert
    return manager._insert(
           ^^^^^^^^^^^^^^^^
  File "/usr/local/lib/python3.11/site-packages/django/db/models/manager.py", line 87, in manager_method
    return getattr(self.get_queryset(), name)(*args, **kwargs)
           ^^^^^^^^^^^^^^^^^^^^^^^^^^^^^^^^^^^^^^^^^^^^^^^^^^^
  File "/usr/local/lib/python3.11/site-packages/django/db/models/query.py", line 1805, in _insert
    return query.get_compiler(using=using).execute_sql(returning_fields)
           ^^^^^^^^^^^^^^^^^^^^^^^^^^^^^^^^^^^^^^^^^^^^^^^^^^^^^^^^^^^^^
  File "/usr/local/lib/python3.11/site-packages/django/db/models/sql/compiler.py", line 1822, in execute_sql
    cursor.execute(sql, params)
  File "/usr/local/lib/python3.11/site-packages/django/db/backends/utils.py", line 102, in execute
    return super().execute(sql, params)
           ^^^^^^^^^^^^^^^^^^^^^^^^^^^^
  File "/usr/local/lib/python3.11/site-packages/django/db/backends/utils.py", line 67, in execute
    return self._execute_with_wrappers(
           ^^^^^^^^^^^^^^^^^^^^^^^^^^^^
  File "/usr/local/lib/python3.11/site-packages/django/db/backends/utils.py", line 80, in _execute_with_wrappers
    return executor(sql, params, many, context)
           ^^^^^^^^^^^^^^^^^^^^^^^^^^^^^^^^^^^^
  File "/usr/local/lib/python3.11/site-packages/django/db/backends/utils.py", line 84, in _execute
    with self.db.wrap_database_errors:
  File "/usr/local/lib/python3.11/site-packages/django/db/utils.py", line 91, in __exit__
    raise dj_exc_value.with_traceback(traceback) from exc_value
  File "/usr/local/lib/python3.11/site-packages/django/db/backends/utils.py", line 89, in _execute
    return self.cursor.execute(sql, params)
           ^^^^^^^^^^^^^^^^^^^^^^^^^^^^^^^^
  File "/usr/local/lib/python3.11/site-packages/django/db/backends/mysql/base.py", line 75, in execute
    return self.cursor.execute(query, args)
           ^^^^^^^^^^^^^^^^^^^^^^^^^^^^^^^^
  File "/usr/local/lib/python3.11/site-packages/pymysql/cursors.py", line 153, in execute
    result = self._query(query)
             ^^^^^^^^^^^^^^^^^^
  File "/usr/local/lib/python3.11/site-packages/pymysql/cursors.py", line 322, in _query
    conn.query(q)
  File "/usr/local/lib/python3.11/site-packages/pymysql/connections.py", line 558, in query
    self._affected_rows = self._read_query_result(unbuffered=unbuffered)
                          ^^^^^^^^^^^^^^^^^^^^^^^^^^^^^^^^^^^^^^^^^^^^^^
  File "/usr/local/lib/python3.11/site-packages/pymysql/connections.py", line 822, in _read_query_result
    result.read()
  File "/usr/local/lib/python3.11/site-packages/pymysql/connections.py", line 1200, in read
    first_packet = self.connection._read_packet()
                   ^^^^^^^^^^^^^^^^^^^^^^^^^^^^^^
  File "/usr/local/lib/python3.11/site-packages/pymysql/connections.py", line 772, in _read_packet
    packet.raise_for_error()
  File "/usr/local/lib/python3.11/site-packages/pymysql/protocol.py", line 221, in raise_for_error
    err.raise_mysql_exception(self._data)
  File "/usr/local/lib/python3.11/site-packages/pymysql/err.py", line 143, in raise_mysql_exception
    raise errorclass(errno, errval)
django.db.utils.IntegrityError: (1048, "Column 'user_id' cannot be null")
"POST /create_category/ HTTP/1.1" 500 202801
Internal Server Error: /create_category/
Traceback (most recent call last):
  File "/usr/local/lib/python3.11/site-packages/django/db/backends/utils.py", line 89, in _execute
    return self.cursor.execute(sql, params)
           ^^^^^^^^^^^^^^^^^^^^^^^^^^^^^^^^
  File "/usr/local/lib/python3.11/site-packages/django/db/backends/mysql/base.py", line 75, in execute
    return self.cursor.execute(query, args)
           ^^^^^^^^^^^^^^^^^^^^^^^^^^^^^^^^
  File "/usr/local/lib/python3.11/site-packages/pymysql/cursors.py", line 153, in execute
    result = self._query(query)
             ^^^^^^^^^^^^^^^^^^
  File "/usr/local/lib/python3.11/site-packages/pymysql/cursors.py", line 322, in _query
    conn.query(q)
  File "/usr/local/lib/python3.11/site-packages/pymysql/connections.py", line 558, in query
    self._affected_rows = self._read_query_result(unbuffered=unbuffered)
                          ^^^^^^^^^^^^^^^^^^^^^^^^^^^^^^^^^^^^^^^^^^^^^^
  File "/usr/local/lib/python3.11/site-packages/pymysql/connections.py", line 822, in _read_query_result
    result.read()
  File "/usr/local/lib/python3.11/site-packages/pymysql/connections.py", line 1200, in read
    first_packet = self.connection._read_packet()
                   ^^^^^^^^^^^^^^^^^^^^^^^^^^^^^^
  File "/usr/local/lib/python3.11/site-packages/pymysql/connections.py", line 772, in _read_packet
    packet.raise_for_error()
  File "/usr/local/lib/python3.11/site-packages/pymysql/protocol.py", line 221, in raise_for_error
    err.raise_mysql_exception(self._data)
  File "/usr/local/lib/python3.11/site-packages/pymysql/err.py", line 143, in raise_mysql_exception
    raise errorclass(errno, errval)
pymysql.err.IntegrityError: (1048, "Column 'user_id' cannot be null")

The above exception was the direct cause of the following exception:

Traceback (most recent call last):
  File "/usr/local/lib/python3.11/site-packages/django/core/handlers/exception.py", line 55, in inner
    response = get_response(request)
               ^^^^^^^^^^^^^^^^^^^^^
  File "/usr/local/lib/python3.11/site-packages/django/core/handlers/base.py", line 197, in _get_response
    response = wrapped_callback(request, *callback_args, **callback_kwargs)
               ^^^^^^^^^^^^^^^^^^^^^^^^^^^^^^^^^^^^^^^^^^^^^^^^^^^^^^^^^^^^
  File "/Users/taramanjimacbookpro/Documents/GitHub/OpenHackU2023_Ritskomachi/todo/views.py", line 208, in create_tag
    form.save()
  File "/usr/local/lib/python3.11/site-packages/django/forms/models.py", line 542, in save
    self.instance.save()
  File "/usr/local/lib/python3.11/site-packages/django/db/models/base.py", line 814, in save
    self.save_base(
  File "/usr/local/lib/python3.11/site-packages/django/db/models/base.py", line 877, in save_base
    updated = self._save_table(
              ^^^^^^^^^^^^^^^^^
  File "/usr/local/lib/python3.11/site-packages/django/db/models/base.py", line 1020, in _save_table
    results = self._do_insert(
              ^^^^^^^^^^^^^^^^
  File "/usr/local/lib/python3.11/site-packages/django/db/models/base.py", line 1061, in _do_insert
    return manager._insert(
           ^^^^^^^^^^^^^^^^
  File "/usr/local/lib/python3.11/site-packages/django/db/models/manager.py", line 87, in manager_method
    return getattr(self.get_queryset(), name)(*args, **kwargs)
           ^^^^^^^^^^^^^^^^^^^^^^^^^^^^^^^^^^^^^^^^^^^^^^^^^^^
  File "/usr/local/lib/python3.11/site-packages/django/db/models/query.py", line 1805, in _insert
    return query.get_compiler(using=using).execute_sql(returning_fields)
           ^^^^^^^^^^^^^^^^^^^^^^^^^^^^^^^^^^^^^^^^^^^^^^^^^^^^^^^^^^^^^
  File "/usr/local/lib/python3.11/site-packages/django/db/models/sql/compiler.py", line 1822, in execute_sql
    cursor.execute(sql, params)
  File "/usr/local/lib/python3.11/site-packages/django/db/backends/utils.py", line 102, in execute
    return super().execute(sql, params)
           ^^^^^^^^^^^^^^^^^^^^^^^^^^^^
  File "/usr/local/lib/python3.11/site-packages/django/db/backends/utils.py", line 67, in execute
    return self._execute_with_wrappers(
           ^^^^^^^^^^^^^^^^^^^^^^^^^^^^
  File "/usr/local/lib/python3.11/site-packages/django/db/backends/utils.py", line 80, in _execute_with_wrappers
    return executor(sql, params, many, context)
           ^^^^^^^^^^^^^^^^^^^^^^^^^^^^^^^^^^^^
  File "/usr/local/lib/python3.11/site-packages/django/db/backends/utils.py", line 84, in _execute
    with self.db.wrap_database_errors:
  File "/usr/local/lib/python3.11/site-packages/django/db/utils.py", line 91, in __exit__
    raise dj_exc_value.with_traceback(traceback) from exc_value
  File "/usr/local/lib/python3.11/site-packages/django/db/backends/utils.py", line 89, in _execute
    return self.cursor.execute(sql, params)
           ^^^^^^^^^^^^^^^^^^^^^^^^^^^^^^^^
  File "/usr/local/lib/python3.11/site-packages/django/db/backends/mysql/base.py", line 75, in execute
    return self.cursor.execute(query, args)
           ^^^^^^^^^^^^^^^^^^^^^^^^^^^^^^^^
  File "/usr/local/lib/python3.11/site-packages/pymysql/cursors.py", line 153, in execute
    result = self._query(query)
             ^^^^^^^^^^^^^^^^^^
  File "/usr/local/lib/python3.11/site-packages/pymysql/cursors.py", line 322, in _query
    conn.query(q)
  File "/usr/local/lib/python3.11/site-packages/pymysql/connections.py", line 558, in query
    self._affected_rows = self._read_query_result(unbuffered=unbuffered)
                          ^^^^^^^^^^^^^^^^^^^^^^^^^^^^^^^^^^^^^^^^^^^^^^
  File "/usr/local/lib/python3.11/site-packages/pymysql/connections.py", line 822, in _read_query_result
    result.read()
  File "/usr/local/lib/python3.11/site-packages/pymysql/connections.py", line 1200, in read
    first_packet = self.connection._read_packet()
                   ^^^^^^^^^^^^^^^^^^^^^^^^^^^^^^
  File "/usr/local/lib/python3.11/site-packages/pymysql/connections.py", line 772, in _read_packet
    packet.raise_for_error()
  File "/usr/local/lib/python3.11/site-packages/pymysql/protocol.py", line 221, in raise_for_error
    err.raise_mysql_exception(self._data)
  File "/usr/local/lib/python3.11/site-packages/pymysql/err.py", line 143, in raise_mysql_exception
    raise errorclass(errno, errval)
django.db.utils.IntegrityError: (1048, "Column 'user_id' cannot be null")
"POST /create_category/ HTTP/1.1" 500 202611
Internal Server Error: /todo_category/
Traceback (most recent call last):
  File "/usr/local/lib/python3.11/site-packages/django/contrib/sessions/backends/base.py", line 187, in _get_session
    return self._session_cache
           ^^^^^^^^^^^^^^^^^^^
AttributeError: 'SessionStore' object has no attribute '_session_cache'

During handling of the above exception, another exception occurred:

Traceback (most recent call last):
  File "/usr/local/lib/python3.11/site-packages/pymysql/connections.py", line 644, in connect
    sock = socket.create_connection(
           ^^^^^^^^^^^^^^^^^^^^^^^^^
  File "/usr/local/Cellar/python@3.11/3.11.4_1/Frameworks/Python.framework/Versions/3.11/lib/python3.11/socket.py", line 851, in create_connection
    raise exceptions[0]
  File "/usr/local/Cellar/python@3.11/3.11.4_1/Frameworks/Python.framework/Versions/3.11/lib/python3.11/socket.py", line 836, in create_connection
    sock.connect(sa)
TimeoutError: timed out

During handling of the above exception, another exception occurred:

Traceback (most recent call last):
  File "/usr/local/lib/python3.11/site-packages/django/db/backends/base/base.py", line 289, in ensure_connection
    self.connect()
  File "/usr/local/lib/python3.11/site-packages/django/utils/asyncio.py", line 26, in inner
    return func(*args, **kwargs)
           ^^^^^^^^^^^^^^^^^^^^^
  File "/usr/local/lib/python3.11/site-packages/django/db/backends/base/base.py", line 270, in connect
    self.connection = self.get_new_connection(conn_params)
                      ^^^^^^^^^^^^^^^^^^^^^^^^^^^^^^^^^^^^
  File "/usr/local/lib/python3.11/site-packages/django/utils/asyncio.py", line 26, in inner
    return func(*args, **kwargs)
           ^^^^^^^^^^^^^^^^^^^^^
  File "/usr/local/lib/python3.11/site-packages/django/db/backends/mysql/base.py", line 247, in get_new_connection
    connection = Database.connect(**conn_params)
                 ^^^^^^^^^^^^^^^^^^^^^^^^^^^^^^^
  File "/usr/local/lib/python3.11/site-packages/pymysql/connections.py", line 358, in __init__
    self.connect()
  File "/usr/local/lib/python3.11/site-packages/pymysql/connections.py", line 711, in connect
    raise exc
pymysql.err.OperationalError: (2003, "Can't connect to MySQL server on 'en1ehf30yom7txe7.cbetxkdyhwsb.us-east-1.rds.amazonaws.com' (timed out)")

The above exception was the direct cause of the following exception:

Traceback (most recent call last):
  File "/usr/local/lib/python3.11/site-packages/django/core/handlers/exception.py", line 55, in inner
    response = get_response(request)
               ^^^^^^^^^^^^^^^^^^^^^
  File "/usr/local/lib/python3.11/site-packages/django/core/handlers/base.py", line 197, in _get_response
    response = wrapped_callback(request, *callback_args, **callback_kwargs)
               ^^^^^^^^^^^^^^^^^^^^^^^^^^^^^^^^^^^^^^^^^^^^^^^^^^^^^^^^^^^^
  File "/usr/local/lib/python3.11/site-packages/django/views/generic/base.py", line 104, in view
    return self.dispatch(request, *args, **kwargs)
           ^^^^^^^^^^^^^^^^^^^^^^^^^^^^^^^^^^^^^^^
  File "/usr/local/lib/python3.11/site-packages/django/contrib/auth/mixins.py", line 71, in dispatch
    if not request.user.is_authenticated:
           ^^^^^^^^^^^^^^^^^^^^^^^^^^^^^
  File "/usr/local/lib/python3.11/site-packages/django/utils/functional.py", line 266, in inner
    self._setup()
  File "/usr/local/lib/python3.11/site-packages/django/utils/functional.py", line 419, in _setup
    self._wrapped = self._setupfunc()
                    ^^^^^^^^^^^^^^^^^
  File "/usr/local/lib/python3.11/site-packages/django/contrib/auth/middleware.py", line 25, in <lambda>
    request.user = SimpleLazyObject(lambda: get_user(request))
                                            ^^^^^^^^^^^^^^^^^
  File "/usr/local/lib/python3.11/site-packages/django/contrib/auth/middleware.py", line 11, in get_user
    request._cached_user = auth.get_user(request)
                           ^^^^^^^^^^^^^^^^^^^^^^
  File "/usr/local/lib/python3.11/site-packages/django/contrib/auth/__init__.py", line 191, in get_user
    user_id = _get_user_session_key(request)
              ^^^^^^^^^^^^^^^^^^^^^^^^^^^^^^
  File "/usr/local/lib/python3.11/site-packages/django/contrib/auth/__init__.py", line 60, in _get_user_session_key
    return get_user_model()._meta.pk.to_python(request.session[SESSION_KEY])
                                               ~~~~~~~~~~~~~~~^^^^^^^^^^^^^
  File "/usr/local/lib/python3.11/site-packages/django/contrib/sessions/backends/base.py", line 53, in __getitem__
    return self._session[key]
           ^^^^^^^^^^^^^
  File "/usr/local/lib/python3.11/site-packages/django/contrib/sessions/backends/base.py", line 192, in _get_session
    self._session_cache = self.load()
                          ^^^^^^^^^^^
  File "/usr/local/lib/python3.11/site-packages/django/contrib/sessions/backends/db.py", line 42, in load
    s = self._get_session_from_db()
        ^^^^^^^^^^^^^^^^^^^^^^^^^^^
  File "/usr/local/lib/python3.11/site-packages/django/contrib/sessions/backends/db.py", line 32, in _get_session_from_db
    return self.model.objects.get(
           ^^^^^^^^^^^^^^^^^^^^^^^
  File "/usr/local/lib/python3.11/site-packages/django/db/models/manager.py", line 87, in manager_method
    return getattr(self.get_queryset(), name)(*args, **kwargs)
           ^^^^^^^^^^^^^^^^^^^^^^^^^^^^^^^^^^^^^^^^^^^^^^^^^^^
  File "/usr/local/lib/python3.11/site-packages/django/db/models/query.py", line 633, in get
    num = len(clone)
          ^^^^^^^^^^
  File "/usr/local/lib/python3.11/site-packages/django/db/models/query.py", line 380, in __len__
    self._fetch_all()
  File "/usr/local/lib/python3.11/site-packages/django/db/models/query.py", line 1881, in _fetch_all
    self._result_cache = list(self._iterable_class(self))
                         ^^^^^^^^^^^^^^^^^^^^^^^^^^^^^^^^
  File "/usr/local/lib/python3.11/site-packages/django/db/models/query.py", line 91, in __iter__
    results = compiler.execute_sql(
              ^^^^^^^^^^^^^^^^^^^^^
  File "/usr/local/lib/python3.11/site-packages/django/db/models/sql/compiler.py", line 1560, in execute_sql
    cursor = self.connection.cursor()
             ^^^^^^^^^^^^^^^^^^^^^^^^
  File "/usr/local/lib/python3.11/site-packages/django/utils/asyncio.py", line 26, in inner
    return func(*args, **kwargs)
           ^^^^^^^^^^^^^^^^^^^^^
  File "/usr/local/lib/python3.11/site-packages/django/db/backends/base/base.py", line 330, in cursor
    return self._cursor()
           ^^^^^^^^^^^^^^
  File "/usr/local/lib/python3.11/site-packages/django/db/backends/base/base.py", line 306, in _cursor
    self.ensure_connection()
  File "/usr/local/lib/python3.11/site-packages/django/utils/asyncio.py", line 26, in inner
    return func(*args, **kwargs)
           ^^^^^^^^^^^^^^^^^^^^^
  File "/usr/local/lib/python3.11/site-packages/django/db/backends/base/base.py", line 288, in ensure_connection
    with self.wrap_database_errors:
  File "/usr/local/lib/python3.11/site-packages/django/db/utils.py", line 91, in __exit__
    raise dj_exc_value.with_traceback(traceback) from exc_value
  File "/usr/local/lib/python3.11/site-packages/django/db/backends/base/base.py", line 289, in ensure_connection
    self.connect()
  File "/usr/local/lib/python3.11/site-packages/django/utils/asyncio.py", line 26, in inner
    return func(*args, **kwargs)
           ^^^^^^^^^^^^^^^^^^^^^
  File "/usr/local/lib/python3.11/site-packages/django/db/backends/base/base.py", line 270, in connect
    self.connection = self.get_new_connection(conn_params)
                      ^^^^^^^^^^^^^^^^^^^^^^^^^^^^^^^^^^^^
  File "/usr/local/lib/python3.11/site-packages/django/utils/asyncio.py", line 26, in inner
    return func(*args, **kwargs)
           ^^^^^^^^^^^^^^^^^^^^^
  File "/usr/local/lib/python3.11/site-packages/django/db/backends/mysql/base.py", line 247, in get_new_connection
    connection = Database.connect(**conn_params)
                 ^^^^^^^^^^^^^^^^^^^^^^^^^^^^^^^
  File "/usr/local/lib/python3.11/site-packages/pymysql/connections.py", line 358, in __init__
    self.connect()
  File "/usr/local/lib/python3.11/site-packages/pymysql/connections.py", line 711, in connect
    raise exc
django.db.utils.OperationalError: (2003, "Can't connect to MySQL server on 'en1ehf30yom7txe7.cbetxkdyhwsb.us-east-1.rds.amazonaws.com' (timed out)")
"GET /todo_category/ HTTP/1.1" 500 264681
